Workbook
Name balanceSh_RG: '02. Nhap lieu tai chinh_RG'!$D$11:$H$57
Name CountBlankBCTC_RG: '03. Dulieutaichinhlamsach_RG'!$K$2
Name CountNegProvision_RG: '02. Nhap lieu tai chinh_RG'!$P$2
Name genInfo_RG: '02. Nhap lieu tai chinh_RG'!$D$7:$H$9
Name incomeStmt_RG: '02. Nhap lieu tai chinh_RG'!$D$59:$H$80
Name CountBlankTTC: '01. Thong tin chung'!$B$10
Name custInfo: '01. Thong tin chung'!$B$3:$B$9
Name balanceSh: '02. Nhap lieu tai chinh_DD'!$D$11:$H$128
Name CountNegProvision: '02. Nhap lieu tai chinh_DD'!$P$2
Name genInfo: '02. Nhap lieu tai chinh_DD'!$D$7:$H$9
Name incomeStmt: '02. Nhap lieu tai chinh_DD'!$D$130:$H$155
Name CountBlankBCTC: '03. Dulieutaichinhlamsach_DD'!$K$2

Sheet Financial_Report1
A1: code | B1: name | C1: =D1-1 | D1: =E1-1 | E1: ='01. Thong tin chung'!B7 | F1: ='01. Thong tin chung'!B8
A2: BS001 | B2: TỔNG TÀI SẢN | C2: =IF('01. Thong tin chung'!$B$9="Đầy đủ", IF(ISBLANK('06. Phan tich tai chinh_DD'!B9),0,'06. Phan tich tai chinh_DD'!B9),IF(ISBLANK('06. Phan tich tai chinh_RG'!B9),0,'06. Phan tich tai chinh_RG'!B9)) | D2: =IF('01. Thong tin chung'!$B$9="Đầy đủ", IF(ISBLANK('06. Phan tich tai chinh_DD'!C9),0,'06. Phan tich tai chinh_DD'!C9),IF(ISBLANK('06. Phan tich tai chinh_RG'!C9),0,'06. Phan tich tai chinh_RG'!C9)) | E2: =IF('01. Thong tin chung'!$B$9="Đầy đủ", IF(ISBLANK('06. Phan tich tai chinh_DD'!D9),0,'06. Phan tich tai chinh_DD'!D9),IF(ISBLANK('06. Phan tich tai chinh_RG'!D9),0,'06. Phan tich tai chinh_RG'!D9)) | F2: =IF('01. Thong tin chung'!$B$9="Đầy đủ", IF(ISBLANK('06. Phan tich tai chinh_DD'!G9),0,'06. Phan tich tai chinh_DD'!G9),IF(ISBLANK('06. Phan tich tai chinh_RG'!G9),0,'06. Phan tich tai chinh_RG'!G9))
A3: BS002 | B3: A. Tài sản ngắn hạn | C3: =IF('01. Thong tin chung'!$B$9="Đầy đủ",'06. Phan tich tai chinh_DD'!B10,-99999) | D3: =IF('01. Thong tin chung'!$B$9="Đầy đủ",'06. Phan tich tai chinh_DD'!C10,-99999) | E3: =IF('01. Thong tin chung'!$B$9="Đầy đủ",'06. Phan tich tai chinh_DD'!D10,-99999) | F3: =IF('01. Thong tin chung'!$B$9="Đầy đủ",'06. Phan tich tai chinh_DD'!G10,-99999)
A4: BS003 | B4: I. Tiền và các khoản tương đương tiền | C4: =IF('01. Thong tin chung'!$B$9="Đầy đủ", IF(ISBLANK('06. Phan tich tai chinh_DD'!B11),0,'06. Phan tich tai chinh_DD'!B11),IF(ISBLANK('06. Phan tich tai chinh_RG'!B10),0,'06. Phan tich tai chinh_RG'!B10)) | D4: =IF('01. Thong tin chung'!$B$9="Đầy đủ", IF(ISBLANK('06. Phan tich tai chinh_DD'!C11),0,'06. Phan tich tai chinh_DD'!C11),IF(ISBLANK('06. Phan tich tai chinh_RG'!C10),0,'06. Phan tich tai chinh_RG'!C10)) | E4: =IF('01. Thong tin chung'!$B$9="Đầy đủ", IF(ISBLANK('06. Phan tich tai chinh_DD'!D11),0,'06. Phan tich tai chinh_DD'!D11),IF(ISBLANK('06. Phan tich tai chinh_RG'!D10),0,'06. Phan tich tai chinh_RG'!D10)) | F4: =IF('01. Thong tin chung'!$B$9="Đầy đủ", IF(ISBLANK('06. Phan tich tai chinh_DD'!G11),0,'06. Phan tich tai chinh_DD'!G11),IF(ISBLANK('06. Phan tich tai chinh_RG'!G10),0,'06. Phan tich tai chinh_RG'!G10))
A5: BS022 | B5: 1. Tiền mặt | C5: =IF('01. Thong tin chung'!$B$9="Đầy đủ",'06. Phan tich tai chinh_DD'!B12,-99999) | D5: =IF('01. Thong tin chung'!$B$9="Đầy đủ",'06. Phan tich tai chinh_DD'!C12,-99999) | E5: =IF('01. Thong tin chung'!$B$9="Đầy đủ",'06. Phan tich tai chinh_DD'!D12,-99999) | F5: =IF('01. Thong tin chung'!$B$9="Đầy đủ",'06. Phan tich tai chinh_DD'!G12,-99999)
A6: BS023 | B6: 2. Tiền gửi ngân hàng | C6: =IF('01. Thong tin chung'!$B$9="Đầy đủ",'06. Phan tich tai chinh_DD'!B13,-99999) | D6: =IF('01. Thong tin chung'!$B$9="Đầy đủ",'06. Phan tich tai chinh_DD'!C13,-99999) | E6: =IF('01. Thong tin chung'!$B$9="Đầy đủ",'06. Phan tich tai chinh_DD'!D13,-99999) | F6: =IF('01. Thong tin chung'!$B$9="Đầy đủ",'06. Phan tich tai chinh_DD'!G13,-99999)
A7: BS024 | B7: 3. Tiền đang chuyển | C7: =IF('01. Thong tin chung'!$B$9="Đầy đủ",'06. Phan tich tai chinh_DD'!B14,-99999) | D7: =IF('01. Thong tin chung'!$B$9="Đầy đủ",'06. Phan tich tai chinh_DD'!C14,-99999) | E7: =IF('01. Thong tin chung'!$B$9="Đầy đủ",'06. Phan tich tai chinh_DD'!D14,-99999) | F7: =IF('01. Thong tin chung'!$B$9="Đầy đủ",'06. Phan tich tai chinh_DD'!G14,-99999)
A8: BS025 | B8: 4. Tiền (trong trường hợp Báo cáo không có 3 thông tin trên) | C8: =IF('01. Thong tin chung'!$B$9="Đầy đủ",'06. Phan tich tai chinh_DD'!B15,-99999) | D8: =IF('01. Thong tin chung'!$B$9="Đầy đủ",'06. Phan tich tai chinh_DD'!C15,-99999) | E8: =IF('01. Thong tin chung'!$B$9="Đầy đủ",'06. Phan tich tai chinh_DD'!D15,-99999) | F8: =IF('01. Thong tin chung'!$B$9="Đầy đủ",'06. Phan tich tai chinh_DD'!G15,-99999)
A9: BS026 | B9: 5. Các khoản tương đương tiền | C9: =IF('01. Thong tin chung'!$B$9="Đầy đủ",'06. Phan tich tai chinh_DD'!B16,-99999) | D9: =IF('01. Thong tin chung'!$B$9="Đầy đủ",'06. Phan tich tai chinh_DD'!C16,-99999) | E9: =IF('01. Thong tin chung'!$B$9="Đầy đủ",'06. Phan tich tai chinh_DD'!D16,-99999) | F9: =IF('01. Thong tin chung'!$B$9="Đầy đủ",'06. Phan tich tai chinh_DD'!G16,-99999)
A10: BS119 | B10: II. Đầu tư tài chính | C10: =IF('01. Thong tin chung'!$B$9="Rút gọn",'06. Phan tich tai chinh_RG'!B11,-99999) | D10: =IF('01. Thong tin chung'!$B$9="Rút gọn",'06. Phan tich tai chinh_RG'!C11,-99999) | E10: =IF('01. Thong tin chung'!$B$9="Rút gọn",'06. Phan tich tai chinh_RG'!D11,-99999) | F10: =IF('01. Thong tin chung'!$B$9="Rút gọn",'06. Phan tich tai chinh_RG'!G11,-99999)
A11: BS120 | B11: 1. Chứng khoán kinh doanh | C11: =IF('01. Thong tin chung'!$B$9="Rút gọn",'06. Phan tich tai chinh_RG'!B12,-99999) | D11: =IF('01. Thong tin chung'!$B$9="Rút gọn",'06. Phan tich tai chinh_RG'!C12,-99999) | E11: =IF('01. Thong tin chung'!$B$9="Rút gọn",'06. Phan tich tai chinh_RG'!D12,-99999) | F11: =IF('01. Thong tin chung'!$B$9="Rút gọn",'06. Phan tich tai chinh_RG'!G12,-99999)
A12: BS121 | B12: 2. Đầu tư nắm giữ đến ngày đáo hạn | C12: =IF('01. Thong tin chung'!$B$9="Rút gọn",'06. Phan tich tai chinh_RG'!B13,-99999) | D12: =IF('01. Thong tin chung'!$B$9="Rút gọn",'06. Phan tich tai chinh_RG'!C13,-99999) | E12: =IF('01. Thong tin chung'!$B$9="Rút gọn",'06. Phan tich tai chinh_RG'!D13,-99999) | F12: =IF('01. Thong tin chung'!$B$9="Rút gọn",'06. Phan tich tai chinh_RG'!G13,-99999)
A13: BS122 | B13: 3. Đầu tư góp vốn vào đơn vị khác | C13: =IF('01. Thong tin chung'!$B$9="Rút gọn",'06. Phan tich tai chinh_RG'!B14,-99999) | D13: =IF('01. Thong tin chung'!$B$9="Rút gọn",'06. Phan tich tai chinh_RG'!C14,-99999) | E13: =IF('01. Thong tin chung'!$B$9="Rút gọn",'06. Phan tich tai chinh_RG'!D14,-99999) | F13: =IF('01. Thong tin chung'!$B$9="Rút gọn",'06. Phan tich tai chinh_RG'!G14,-99999)
A14: BS123 | B14: 4. Dự phòng tổn thất đầu tư tài chính (*) | C14: =IF('01. Thong tin chung'!$B$9="Rút gọn",'06. Phan tich tai chinh_RG'!B15,-99999) | D14: =IF('01. Thong tin chung'!$B$9="Rút gọn",'06. Phan tich tai chinh_RG'!C15,-99999) | E14: =IF('01. Thong tin chung'!$B$9="Rút gọn",'06. Phan tich tai chinh_RG'!D15,-99999) | F14: =IF('01. Thong tin chung'!$B$9="Rút gọn",'06. Phan tich tai chinh_RG'!G15,-99999)
A15: BS004 | B15: II. Các khoản đầu tư tài chính ngắn hạn | C15: =IF('01. Thong tin chung'!$B$9="Đầy đủ",'06. Phan tich tai chinh_DD'!B17,-99999) | D15: =IF('01. Thong tin chung'!$B$9="Đầy đủ",'06. Phan tich tai chinh_DD'!C17,-99999) | E15: =IF('01. Thong tin chung'!$B$9="Đầy đủ",'06. Phan tich tai chinh_DD'!D17,-99999) | F15: =IF('01. Thong tin chung'!$B$9="Đầy đủ",'06. Phan tich tai chinh_DD'!G17,-99999)
A16: BS027 | B16: 1. Chứng khoán đầu tư ngắn hạn | C16: =IF('01. Thong tin chung'!$B$9="Đầy đủ",'06. Phan tich tai chinh_DD'!B18,-99999) | D16: =IF('01. Thong tin chung'!$B$9="Đầy đủ",'06. Phan tich tai chinh_DD'!C18,-99999) | E16: =IF('01. Thong tin chung'!$B$9="Đầy đủ",'06. Phan tich tai chinh_DD'!D18,-99999) | F16: =IF('01. Thong tin chung'!$B$9="Đầy đủ",'06. Phan tich tai chinh_DD'!G18,-99999)
A17: BS028 | B17: 2. Đầu tư ngắn hạn khác | C17: =IF('01. Thong tin chung'!$B$9="Đầy đủ",'06. Phan tich tai chinh_DD'!B19,-99999) | D17: =IF('01. Thong tin chung'!$B$9="Đầy đủ",'06. Phan tich tai chinh_DD'!C19,-99999) | E17: =IF('01. Thong tin chung'!$B$9="Đầy đủ",'06. Phan tich tai chinh_DD'!D19,-99999) | F17: =IF('01. Thong tin chung'!$B$9="Đầy đủ",'06. Phan tich tai chinh_DD'!G19,-99999)
A18: BS029 | B18: 3. Dự phòng giảm giá đầu tư ngắn hạn | C18: =IF('01. Thong tin chung'!$B$9="Đầy đủ",'06. Phan tich tai chinh_DD'!B20,-99999) | D18: =IF('01. Thong tin chung'!$B$9="Đầy đủ",'06. Phan tich tai chinh_DD'!C20,-99999) | E18: =IF('01. Thong tin chung'!$B$9="Đầy đủ",'06. Phan tich tai chinh_DD'!D20,-99999) | F18: =IF('01. Thong tin chung'!$B$9="Đầy đủ",'06. Phan tich tai chinh_DD'!G20,-99999)
A19: BS030 | B19: 4. Đầu tư tài chính ngắn hạn (trong trường hợp báo cáo không có thông tin) | C19: =IF('01. Thong tin chung'!$B$9="Đầy đủ",'06. Phan tich tai chinh_DD'!B21,-99999) | D19: =IF('01. Thong tin chung'!$B$9="Đầy đủ",'06. Phan tich tai chinh_DD'!C21,-99999) | E19: =IF('01. Thong tin chung'!$B$9="Đầy đủ",'06. Phan tich tai chinh_DD'!D21,-99999) | F19: =IF('01. Thong tin chung'!$B$9="Đầy đủ",'06. Phan tich tai chinh_DD'!G21,-99999)
A20: BS124 | B20: III. Các khoản phải thu | C20: =IF('01. Thong tin chung'!$B$9="Rút gọn",'06. Phan tich tai chinh_RG'!B16,-99999) | D20: =IF('01. Thong tin chung'!$B$9="Rút gọn",'06. Phan tich tai chinh_RG'!C16,-99999) | E20: =IF('01. Thong tin chung'!$B$9="Rút gọn",'06. Phan tich tai chinh_RG'!D16,-99999) | F20: =IF('01. Thong tin chung'!$B$9="Rút gọn",'06. Phan tich tai chinh_RG'!G16,-99999)
A21: BS125 | B21: 1. Phải thu của khách hàng | C21: =IF('01. Thong tin chung'!$B$9="Rút gọn",'06. Phan tich tai chinh_RG'!B17,-99999) | D21: =IF('01. Thong tin chung'!$B$9="Rút gọn",'06. Phan tich tai chinh_RG'!C17,-99999) | E21: =IF('01. Thong tin chung'!$B$9="Rút gọn",'06. Phan tich tai chinh_RG'!D17,-99999) | F21: =IF('01. Thong tin chung'!$B$9="Rút gọn",'06. Phan tich tai chinh_RG'!G17,-99999)
A22: BS126 | B22: 2. Trả trước cho người bán | C22: =IF('01. Thong tin chung'!$B$9="Rút gọn",'06. Phan tich tai chinh_RG'!B18,-99999) | D22: =IF('01. Thong tin chung'!$B$9="Rút gọn",'06. Phan tich tai chinh_RG'!C18,-99999) | E22: =IF('01. Thong tin chung'!$B$9="Rút gọn",'06. Phan tich tai chinh_RG'!D18,-99999) | F22: =IF('01. Thong tin chung'!$B$9="Rút gọn",'06. Phan tich tai chinh_RG'!G18,-99999)
A23: BS127 | B23: 3. Vốn kinh doanh ở đơn vị trực thuộc | C23: =IF('01. Thong tin chung'!$B$9="Rút gọn",'06. Phan tich tai chinh_RG'!B19,-99999) | D23: =IF('01. Thong tin chung'!$B$9="Rút gọn",'06. Phan tich tai chinh_RG'!C19,-99999) | E23: =IF('01. Thong tin chung'!$B$9="Rút gọn",'06. Phan tich tai chinh_RG'!D19,-99999) | F23: =IF('01. Thong tin chung'!$B$9="Rút gọn",'06. Phan tich tai chinh_RG'!G19,-99999)
A24: BS128 | B24: 4. Phải thu khác | C24: =IF('01. Thong tin chung'!$B$9="Rút gọn",'06. Phan tich tai chinh_RG'!B20,-99999) | D24: =IF('01. Thong tin chung'!$B$9="Rút gọn",'06. Phan tich tai chinh_RG'!C20,-99999) | E24: =IF('01. Thong tin chung'!$B$9="Rút gọn",'06. Phan tich tai chinh_RG'!D20,-99999) | F24: =IF('01. Thong tin chung'!$B$9="Rút gọn",'06. Phan tich tai chinh_RG'!G20,-99999)
A25: BS129 | B25: 5. Tài sản thiếu chờ xử lý | C25: =IF('01. Thong tin chung'!$B$9="Rút gọn",'06. Phan tich tai chinh_RG'!B21,-99999) | D25: =IF('01. Thong tin chung'!$B$9="Rút gọn",'06. Phan tich tai chinh_RG'!C21,-99999) | E25: =IF('01. Thong tin chung'!$B$9="Rút gọn",'06. Phan tich tai chinh_RG'!D21,-99999) | F25: =IF('01. Thong tin chung'!$B$9="Rút gọn",'06. Phan tich tai chinh_RG'!G21,-99999)
A26: BS130 | B26: 6. Dự phòng phải thu khó đòi (*) | C26: =IF('01. Thong tin chung'!$B$9="Rút gọn",'06. Phan tich tai chinh_RG'!B22,-99999) | D26: =IF('01. Thong tin chung'!$B$9="Rút gọn",'06. Phan tich tai chinh_RG'!C22,-99999) | E26: =IF('01. Thong tin chung'!$B$9="Rút gọn",'06. Phan tich tai chinh_RG'!D22,-99999) | F26: =IF('01. Thong tin chung'!$B$9="Rút gọn",'06. Phan tich tai chinh_RG'!G22,-99999)
A27: BS005 | B27: III. Các khoản phải thu ngắn hạn | C27: =IF('01. Thong tin chung'!$B$9="Đầy đủ",'06. Phan tich tai chinh_DD'!B22,-99999) | D27: =IF('01. Thong tin chung'!$B$9="Đầy đủ",'06. Phan tich tai chinh_DD'!C22,-99999) | E27: =IF('01. Thong tin chung'!$B$9="Đầy đủ",'06. Phan tich tai chinh_DD'!D22,-99999) | F27: =IF('01. Thong tin chung'!$B$9="Đầy đủ",'06. Phan tich tai chinh_DD'!G22,-99999)
A28: BS031 | B28: 1. Phải thu khách hàng | C28: =IF('01. Thong tin chung'!$B$9="Đầy đủ",'06. Phan tich tai chinh_DD'!B23,-99999) | D28: =IF('01. Thong tin chung'!$B$9="Đầy đủ",'06. Phan tich tai chinh_DD'!C23,-99999) | E28: =IF('01. Thong tin chung'!$B$9="Đầy đủ",'06. Phan tich tai chinh_DD'!D23,-99999) | F28: =IF('01. Thong tin chung'!$B$9="Đầy đủ",'06. Phan tich tai chinh_DD'!G23,-99999)
A29: BS032 | B29: 2. Trả trước cho người bán | C29: =IF('01. Thong tin chung'!$B$9="Đầy đủ",'06. Phan tich tai chinh_DD'!B24,-99999) | D29: =IF('01. Thong tin chung'!$B$9="Đầy đủ",'06. Phan tich tai chinh_DD'!C24,-99999) | E29: =IF('01. Thong tin chung'!$B$9="Đầy đủ",'06. Phan tich tai chinh_DD'!D24,-99999) | F29: =IF('01. Thong tin chung'!$B$9="Đầy đủ",'06. Phan tich tai chinh_DD'!G24,-99999)
A30: BS033 | B30: 3. Phải thu nội bộ ngắn hạn | C30: =IF('01. Thong tin chung'!$B$9="Đầy đủ",'06. Phan tich tai chinh_DD'!B25,-99999) | D30: =IF('01. Thong tin chung'!$B$9="Đầy đủ",'06. Phan tich tai chinh_DD'!C25,-99999) | E30: =IF('01. Thong tin chung'!$B$9="Đầy đủ",'06. Phan tich tai chinh_DD'!D25,-99999) | F30: =IF('01. Thong tin chung'!$B$9="Đầy đủ",'06. Phan tich tai chinh_DD'!G25,-99999)
A31: BS034 | B31: 4. Phải thu theo tiến độ kế hoạch hợp đồng xây dựng | C31: =IF('01. Thong tin chung'!$B$9="Đầy đủ",'06. Phan tich tai chinh_DD'!B26,-99999) | D31: =IF('01. Thong tin chung'!$B$9="Đầy đủ",'06. Phan tich tai chinh_DD'!C26,-99999) | E31: =IF('01. Thong tin chung'!$B$9="Đầy đủ",'06. Phan tich tai chinh_DD'!D26,-99999) | F31: =IF('01. Thong tin chung'!$B$9="Đầy đủ",'06. Phan tich tai chinh_DD'!G26,-99999)
A32: BS035 | B32: 5. Các khoản phải thu khác | C32: =IF('01. Thong tin chung'!$B$9="Đầy đủ",'06. Phan tich tai chinh_DD'!B27,-99999) | D32: =IF('01. Thong tin chung'!$B$9="Đầy đủ",'06. Phan tich tai chinh_DD'!C27,-99999) | E32: =IF('01. Thong tin chung'!$B$9="Đầy đủ",'06. Phan tich tai chinh_DD'!D27,-99999) | F32: =IF('01. Thong tin chung'!$B$9="Đầy đủ",'06. Phan tich tai chinh_DD'!G27,-99999)
A33: BS036 | B33: 6. Dự phòng phải thu ngắn hạn khó đòi | C33: =IF('01. Thong tin chung'!$B$9="Đầy đủ",'06. Phan tich tai chinh_DD'!B28,-99999) | D33: =IF('01. Thong tin chung'!$B$9="Đầy đủ",'06. Phan tich tai chinh_DD'!C28,-99999) | E33: =IF('01. Thong tin chung'!$B$9="Đầy đủ",'06. Phan tich tai chinh_DD'!D28,-99999) | F33: =IF('01. Thong tin chung'!$B$9="Đầy đủ",'06. Phan tich tai chinh_DD'!G28,-99999)
A34: BS006 | B34: IV. Hàng tồn kho | C34: =IF('01. Thong tin chung'!$B$9="Đầy đủ", IF(ISBLANK('06. Phan tich tai chinh_DD'!B29),0,'06. Phan tich tai chinh_DD'!B29),IF(ISBLANK('06. Phan tich tai chinh_RG'!B23),0,'06. Phan tich tai chinh_RG'!B23)) | D34: =IF('01. Thong tin chung'!$B$9="Đầy đủ", IF(ISBLANK('06. Phan tich tai chinh_DD'!C29),0,'06. Phan tich tai chinh_DD'!C29),IF(ISBLANK('06. Phan tich tai chinh_RG'!C23),0,'06. Phan tich tai chinh_RG'!C23)) | E34: =IF('01. Thong tin chung'!$B$9="Đầy đủ", IF(ISBLANK('06. Phan tich tai chinh_DD'!D29),0,'06. Phan tich tai chinh_DD'!D29),IF(ISBLANK('06. Phan tich tai chinh_RG'!D23),0,'06. Phan tich tai chinh_RG'!D23)) | F34: =IF('01. Thong tin chung'!$B$9="Đầy đủ", IF(ISBLANK('06. Phan tich tai chinh_DD'!G29),0,'06. Phan tich tai chinh_DD'!G29),IF(ISBLANK('06. Phan tich tai chinh_RG'!G23),0,'06. Phan tich tai chinh_RG'!G23))
A35: BS037 | B35: 1. Hàng mua đang đi đường | C35: =IF('01. Thong tin chung'!$B$9="Đầy đủ",'06. Phan tich tai chinh_DD'!B30,-99999) | D35: =IF('01. Thong tin chung'!$B$9="Đầy đủ",'06. Phan tich tai chinh_DD'!C30,-99999) | E35: =IF('01. Thong tin chung'!$B$9="Đầy đủ",'06. Phan tich tai chinh_DD'!D30,-99999) | F35: =IF('01. Thong tin chung'!$B$9="Đầy đủ",'06. Phan tich tai chinh_DD'!G30,-99999)
A36: BS038 | B36: 2. Nguyên liệu, vật liệu | C36: =IF('01. Thong tin chung'!$B$9="Đầy đủ",'06. Phan tich tai chinh_DD'!B31,-99999) | D36: =IF('01. Thong tin chung'!$B$9="Đầy đủ",'06. Phan tich tai chinh_DD'!C31,-99999) | E36: =IF('01. Thong tin chung'!$B$9="Đầy đủ",'06. Phan tich tai chinh_DD'!D31,-99999) | F36: =IF('01. Thong tin chung'!$B$9="Đầy đủ",'06. Phan tich tai chinh_DD'!G31,-99999)
A37: BS039 | B37: 3. Công cụ, dụng cụ | C37: =IF('01. Thong tin chung'!$B$9="Đầy đủ",'06. Phan tich tai chinh_DD'!B32,-99999) | D37: =IF('01. Thong tin chung'!$B$9="Đầy đủ",'06. Phan tich tai chinh_DD'!C32,-99999) | E37: =IF('01. Thong tin chung'!$B$9="Đầy đủ",'06. Phan tich tai chinh_DD'!D32,-99999) | F37: =IF('01. Thong tin chung'!$B$9="Đầy đủ",'06. Phan tich tai chinh_DD'!G32,-99999)
A38: BS040 | B38: 4. Chi phí SX, KD dở dang | C38: =IF('01. Thong tin chung'!$B$9="Đầy đủ",'06. Phan tich tai chinh_DD'!B33,-99999) | D38: =IF('01. Thong tin chung'!$B$9="Đầy đủ",'06. Phan tich tai chinh_DD'!C33,-99999) | E38: =IF('01. Thong tin chung'!$B$9="Đầy đủ",'06. Phan tich tai chinh_DD'!D33,-99999) | F38: =IF('01. Thong tin chung'!$B$9="Đầy đủ",'06. Phan tich tai chinh_DD'!G33,-99999)
A39: BS041 | B39: 5. Thành phẩm | C39: =IF('01. Thong tin chung'!$B$9="Đầy đủ",'06. Phan tich tai chinh_DD'!B34,-99999) | D39: =IF('01. Thong tin chung'!$B$9="Đầy đủ",'06. Phan tich tai chinh_DD'!C34,-99999) | E39: =IF('01. Thong tin chung'!$B$9="Đầy đủ",'06. Phan tich tai chinh_DD'!D34,-99999) | F39: =IF('01. Thong tin chung'!$B$9="Đầy đủ",'06. Phan tich tai chinh_DD'!G34,-99999)
A40: BS042 | B40: 6. Hàng hóa | C40: =IF('01. Thong tin chung'!$B$9="Đầy đủ",'06. Phan tich tai chinh_DD'!B35,-99999) | D40: =IF('01. Thong tin chung'!$B$9="Đầy đủ",'06. Phan tich tai chinh_DD'!C35,-99999) | E40: =IF('01. Thong tin chung'!$B$9="Đầy đủ",'06. Phan tich tai chinh_DD'!D35,-99999) | F40: =IF('01. Thong tin chung'!$B$9="Đầy đủ",'06. Phan tich tai chinh_DD'!G35,-99999)
...

Sheet Droplist
A1: VND | C1: Loại BCTC | D1: =IF('01. Thong tin chung'!B9="Đầy đủ",1, IF('01. Thong tin chung'!B9="Rút gọn",2,0))
A2: Triệu VND

Sheet 0. Huong dan

Sheet 01. Thong tin chung
A1: Template BCTC - Hiệu lực từ 05/11/2023
A2: Thông tin chung về khách hàng
A3: Tên Công ty: | B3: CÔNG TY CỔ PHẦN KẾT CẤU THÉP STEELTECH
A4: Mã số thuế (Tax code) | B4: 0319777888
A5: Mã khách hàng (số CIF) | B5: 5162308
A6: Đơn vị tiền tệ sử dụng trong Báo cáo Tài chính: | B6: VND
A7: Năm Tài chính gần nhất: | B7: 2025
A8: Thời điểm tài chính gần nhất | B8: 46022
A9: Loại BCTC | B9: Đầy đủ
A10: CountBlank | B10: =COUNTIF(B3:B9,"")

Sheet 02. Nhap lieu tai chinh_RG
B1: NHẬP SỐ LIỆU VỀ TÀI CHÍNH CỦA KHÁCH HÀNG | I1: Check thông tin báo cáo tài chính
D2: Lưu ý: bắt buộc điền sheet 01. Thông tin chung | F2: Đơn vị: | G2: =IF('01. Thong tin chung'!B6="","",'01. Thong tin chung'!B6) | O2: CountNegProvision | P2: =COUNTIF(D17:H17,">0")+COUNTIF(D24:H24,">0")+COUNTIF(D27:H27,">0")+COUNTIF(D30:H30,">0")+COUNTIF(D33:H33,">0")
B3: I. Bảng cân đối kế toán
D4: =IF(D11<>D38,"Chưa cân số","") | E4: =IF(E11<>E38,"Chưa cân số","") | F4: =IF(F11<>F38,"Chưa cân số","") | G4: =IF(G11<>G38,"Chưa cân số","") | H4: =IF(H11<>H38,"Chưa cân số","")
B5: Chỉ tiêu | C5: Mã số | D5: N-3 | E5: N-2 | F5: N-1 | G5: Thời điểm hiện tại | H5: Dự tính N
B6: Mã số thuế | D6: ='01. Thong tin chung'!$B$4 | E6: ='01. Thong tin chung'!$B$4 | F6: ='01. Thong tin chung'!$B$4 | G6: ='01. Thong tin chung'!$B$4 | H6: ='01. Thong tin chung'!$B$4 | I6: =D6='03. Dulieutaichinhlamsach_RG'!D6 | J6: =E6='03. Dulieutaichinhlamsach_RG'!E6 | K6: =F6='03. Dulieutaichinhlamsach_RG'!F6 | L6: =G6='03. Dulieutaichinhlamsach_RG'!G6 | M6: =H6='03. Dulieutaichinhlamsach_RG'!H6
B7: Năm | I7: =D7='03. Dulieutaichinhlamsach_RG'!D7 | J7: =E7='03. Dulieutaichinhlamsach_RG'!E7 | K7: =F7='03. Dulieutaichinhlamsach_RG'!F7 | L7: =G7='03. Dulieutaichinhlamsach_RG'!G7 | M7: =H7='03. Dulieutaichinhlamsach_RG'!H7
B8: Quý | I8: =D8='03. Dulieutaichinhlamsach_RG'!D8 | J8: =E8='03. Dulieutaichinhlamsach_RG'!E8 | K8: =F8='03. Dulieutaichinhlamsach_RG'!F8 | L8: =G8='03. Dulieutaichinhlamsach_RG'!G8 | M8: =H8='03. Dulieutaichinhlamsach_RG'!H8
B9: Tháng | I9: =D9='03. Dulieutaichinhlamsach_RG'!D9 | J9: =E9='03. Dulieutaichinhlamsach_RG'!E9 | K9: =F9='03. Dulieutaichinhlamsach_RG'!F9 | L9: =G9='03. Dulieutaichinhlamsach_RG'!G9 | M9: =H9='03. Dulieutaichinhlamsach_RG'!H9
B10: Đơn vị tính | D10: =$G$2 | E10: =$G$2 | F10: =$G$2 | G10: =$G$2 | H10: =$G$2 | I10: =D10='03. Dulieutaichinhlamsach_RG'!D10 | J10: =E10='03. Dulieutaichinhlamsach_RG'!E10 | K10: =F10='03. Dulieutaichinhlamsach_RG'!F10 | L10: =G10='03. Dulieutaichinhlamsach_RG'!G10 | M10: =H10='03. Dulieutaichinhlamsach_RG'!H10
B11: TỔNG CỘNG TÀI SẢN | I11: =D11='03. Dulieutaichinhlamsach_RG'!D11 | J11: =E11='03. Dulieutaichinhlamsach_RG'!E11 | K11: =F11='03. Dulieutaichinhlamsach_RG'!F11 | L11: =G11='03. Dulieutaichinhlamsach_RG'!G11 | M11: =H11='03. Dulieutaichinhlamsach_RG'!H11
B12: I. Tiền và các khoản tương đương tiền | I12: =D12='03. Dulieutaichinhlamsach_RG'!D12 | J12: =E12='03. Dulieutaichinhlamsach_RG'!E12 | K12: =F12='03. Dulieutaichinhlamsach_RG'!F12 | L12: =G12='03. Dulieutaichinhlamsach_RG'!G12 | M12: =H12='03. Dulieutaichinhlamsach_RG'!H12
B13: II. Đầu tư tài chính | I13: =D13='03. Dulieutaichinhlamsach_RG'!D13 | J13: =E13='03. Dulieutaichinhlamsach_RG'!E13 | K13: =F13='03. Dulieutaichinhlamsach_RG'!F13 | L13: =G13='03. Dulieutaichinhlamsach_RG'!G13 | M13: =H13='03. Dulieutaichinhlamsach_RG'!H13
B14: 1. Chứng khoán kinh doanh | I14: =D14='03. Dulieutaichinhlamsach_RG'!D14 | J14: =E14='03. Dulieutaichinhlamsach_RG'!E14 | K14: =F14='03. Dulieutaichinhlamsach_RG'!F14 | L14: =G14='03. Dulieutaichinhlamsach_RG'!G14 | M14: =H14='03. Dulieutaichinhlamsach_RG'!H14
B15: 2. Đầu tư nắm giữ đến ngày đáo hạn | I15: =D15='03. Dulieutaichinhlamsach_RG'!D15 | J15: =E15='03. Dulieutaichinhlamsach_RG'!E15 | K15: =F15='03. Dulieutaichinhlamsach_RG'!F15 | L15: =G15='03. Dulieutaichinhlamsach_RG'!G15 | M15: =H15='03. Dulieutaichinhlamsach_RG'!H15
B16: 3. Đầu tư góp vốn vào đơn vị khác | I16: =D16='03. Dulieutaichinhlamsach_RG'!D16 | J16: =E16='03. Dulieutaichinhlamsach_RG'!E16 | K16: =F16='03. Dulieutaichinhlamsach_RG'!F16 | L16: =G16='03. Dulieutaichinhlamsach_RG'!G16 | M16: =H16='03. Dulieutaichinhlamsach_RG'!H16
B17: 4. Dự phòng tổn thất đầu tư tài chính (*) | I17: =D17='03. Dulieutaichinhlamsach_RG'!D17 | J17: =E17='03. Dulieutaichinhlamsach_RG'!E17 | K17: =F17='03. Dulieutaichinhlamsach_RG'!F17 | L17: =G17='03. Dulieutaichinhlamsach_RG'!G17 | M17: =H17='03. Dulieutaichinhlamsach_RG'!H17
B18: III. Các khoản phải thu | I18: =D18='03. Dulieutaichinhlamsach_RG'!D18 | J18: =E18='03. Dulieutaichinhlamsach_RG'!E18 | K18: =F18='03. Dulieutaichinhlamsach_RG'!F18 | L18: =G18='03. Dulieutaichinhlamsach_RG'!G18 | M18: =H18='03. Dulieutaichinhlamsach_RG'!H18
B19: 1. Phải thu của khách hàng | I19: =D19='03. Dulieutaichinhlamsach_RG'!D19 | J19: =E19='03. Dulieutaichinhlamsach_RG'!E19 | K19: =F19='03. Dulieutaichinhlamsach_RG'!F19 | L19: =G19='03. Dulieutaichinhlamsach_RG'!G19 | M19: =H19='03. Dulieutaichinhlamsach_RG'!H19
B20: 2. Trả trước cho người bán | I20: =D20='03. Dulieutaichinhlamsach_RG'!D20 | J20: =E20='03. Dulieutaichinhlamsach_RG'!E20 | K20: =F20='03. Dulieutaichinhlamsach_RG'!F20 | L20: =G20='03. Dulieutaichinhlamsach_RG'!G20 | M20: =H20='03. Dulieutaichinhlamsach_RG'!H20
B21: 3. Vốn kinh doanh ở đơn vị trực thuộc | I21: =D21='03. Dulieutaichinhlamsach_RG'!D21 | J21: =E21='03. Dulieutaichinhlamsach_RG'!E21 | K21: =F21='03. Dulieutaichinhlamsach_RG'!F21 | L21: =G21='03. Dulieutaichinhlamsach_RG'!G21 | M21: =H21='03. Dulieutaichinhlamsach_RG'!H21
B22: 4. Phải thu khác | I22: =D22='03. Dulieutaichinhlamsach_RG'!D22 | J22: =E22='03. Dulieutaichinhlamsach_RG'!E22 | K22: =F22='03. Dulieutaichinhlamsach_RG'!F22 | L22: =G22='03. Dulieutaichinhlamsach_RG'!G22 | M22: =H22='03. Dulieutaichinhlamsach_RG'!H22
... B58: II. Báo cáo kết quả hoạt động SXKD | I58: =D58='03. Dulieutaichinhlamsach_RG'!D58 | J58: =E58='03. Dulieutaichinhlamsach_RG'!E58 | K58: =F58='03. Dulieutaichinhlamsach_RG'!F58 | L58: =G58='03. Dulieutaichinhlamsach_RG'!G58 | M58: =H58='03. Dulieutaichinhlamsach_RG'!H58
B59: Doanh thu bán hàng và cung cấp dịch vụ | I59: =D59='03. Dulieutaichinhlamsach_RG'!D72 | J59: =E59='03. Dulieutaichinhlamsach_RG'!E72 | K59: =F59='03. Dulieutaichinhlamsach_RG'!F72 | L59: =G59='03. Dulieutaichinhlamsach_RG'!G72 | M59: =H59='03. Dulieutaichinhlamsach_RG'!H72
B60: Các khoản giảm trừ doanh thu | I60: =D60='03. Dulieutaichinhlamsach_RG'!D73 | J60: =E60='03. Dulieutaichinhlamsach_RG'!E73 | K60: =F60='03. Dulieutaichinhlamsach_RG'!F73 | L60: =G60='03. Dulieutaichinhlamsach_RG'!G73 | M60: =H60='03. Dulieutaichinhlamsach_RG'!H73
B61: - Chiết khấu | I61: =D61='03. Dulieutaichinhlamsach_RG'!D74 | J61: =E61='03. Dulieutaichinhlamsach_RG'!E74 | K61: =F61='03. Dulieutaichinhlamsach_RG'!F74 | L61: =G61='03. Dulieutaichinhlamsach_RG'!G74 | M61: =H61='03. Dulieutaichinhlamsach_RG'!H74
B62: - Giảm giá | I62: =D62='03. Dulieutaichinhlamsach_RG'!D75 | J62: =E62='03. Dulieutaichinhlamsach_RG'!E75 | K62: =F62='03. Dulieutaichinhlamsach_RG'!F75 | L62: =G62='03. Dulieutaichinhlamsach_RG'!G75 | M62: =H62='03. Dulieutaichinhlamsach_RG'!H75
B63: - Hàng bán bị trả lại | I63: =D63='03. Dulieutaichinhlamsach_RG'!D76 | J63: =E63='03. Dulieutaichinhlamsach_RG'!E76 | K63: =F63='03. Dulieutaichinhlamsach_RG'!F76 | L63: =G63='03. Dulieutaichinhlamsach_RG'!G76 | M63: =H63='03. Dulieutaichinhlamsach_RG'!H76
B64: - Thuế VAT, thuế xuất khẩu | I64: =D64='03. Dulieutaichinhlamsach_RG'!D77 | J64: =E64='03. Dulieutaichinhlamsach_RG'!E77 | K64: =F64='03. Dulieutaichinhlamsach_RG'!F77 | L64: =G64='03. Dulieutaichinhlamsach_RG'!G77 | M64: =H64='03. Dulieutaichinhlamsach_RG'!H77
B65: Doanh thu thuần về bán hàng và cung cấp dịch vụ | I65: =D65='03. Dulieutaichinhlamsach_RG'!D78 | J65: =E65='03. Dulieutaichinhlamsach_RG'!E78 | K65: =F65='03. Dulieutaichinhlamsach_RG'!F78 | L65: =G65='03. Dulieutaichinhlamsach_RG'!G78 | M65: =H65='03. Dulieutaichinhlamsach_RG'!H78
B66: Giá vốn hàng bán | I66: =D66='03. Dulieutaichinhlamsach_RG'!D79 | J66: =E66='03. Dulieutaichinhlamsach_RG'!E79 | K66: =F66='03. Dulieutaichinhlamsach_RG'!F79 | L66: =G66='03. Dulieutaichinhlamsach_RG'!G79 | M66: =H66='03. Dulieutaichinhlamsach_RG'!H79
B67: - Tr/đó: Khấu hao trong giá vốn hàng bán | I67: =D67='03. Dulieutaichinhlamsach_RG'!D80 | J67: =E67='03. Dulieutaichinhlamsach_RG'!E80 | K67: =F67='03. Dulieutaichinhlamsach_RG'!F80 | L67: =G67='03. Dulieutaichinhlamsach_RG'!G80 | M67: =H67='03. Dulieutaichinhlamsach_RG'!H80
B68: Lợi nhuận gộp về bán hàng và cung cấp dịch vụ | I68: =D68='03. Dulieutaichinhlamsach_RG'!D81 | J68: =E68='03. Dulieutaichinhlamsach_RG'!E81 | K68: =F68='03. Dulieutaichinhlamsach_RG'!F81 | L68: =G68='03. Dulieutaichinhlamsach_RG'!G81 | M68: =H68='03. Dulieutaichinhlamsach_RG'!H81
B69: Doanh thu hoạt động tài chính | I69: =D69='03. Dulieutaichinhlamsach_RG'!D82 | J69: =E69='03. Dulieutaichinhlamsach_RG'!E82 | K69: =F69='03. Dulieutaichinhlamsach_RG'!F82 | L69: =G69='03. Dulieutaichinhlamsach_RG'!G82 | M69: =H69='03. Dulieutaichinhlamsach_RG'!H82
B70: Chi phí tài chính | I70: =D70='03. Dulieutaichinhlamsach_RG'!D83 | J70: =E70='03. Dulieutaichinhlamsach_RG'!E83 | K70: =F70='03. Dulieutaichinhlamsach_RG'!F83 | L70: =G70='03. Dulieutaichinhlamsach_RG'!G83 | M70: =H70='03. Dulieutaichinhlamsach_RG'!H83
... B80: Lãi cơ bản trên cổ phiếu | I80: =D80='03. Dulieutaichinhlamsach_RG'!D93 | J80: =E80='03. Dulieutaichinhlamsach_RG'!E93 | K80: =F80='03. Dulieutaichinhlamsach_RG'!F93 | L80: =G80='03. Dulieutaichinhlamsach_RG'!G93 | M80: =H80='03. Dulieutaichinhlamsach_RG'!H93

Sheet 03. Dulieutaichinhlamsach_RG
B1: NHẬP SỐ LIỆU VỀ TÀI CHÍNH CỦA KHÁCH HÀNG
C2: =IF(OR(E11=0,F11=0),"Đề nghị nhấp số liệu tối thiểu 2 năm gần nhất"," ") | F2: Đơn vị: | G2: ='01. Thong tin chung'!B6 | H2: =G2 | J2: CountBlankBCTC | K2: =COUNTIF(D4:G4,"Chưa cân số") + COUNTIF(G2,"")
B3: I. Bảng cân đối kế toán
D4: =IF(D11<>D38,"Chưa cân số", " ") | E4: =IF(E11<>E38,"Chưa cân số", " ") | F4: =IF(F11<>F38,"Chưa cân số", " ") | G4: =IF(G11<>G38,"Chưa cân số", " ") | H4: =IF(H11<>H38,"Chưa cân số", " ")
B5: Chỉ tiêu | C5: Mã số | D5: =E5-1 | E5: =F5-1 | F5: ='01. Thong tin chung'!B7 | G5: ='01. Thong tin chung'!B8 | H5: ="Dự tính " &F5+1
B6: Mã số thuế | D6: ='02. Nhap lieu tai chinh_RG'!D6 | E6: ='02. Nhap lieu tai chinh_RG'!E6 | F6: ='02. Nhap lieu tai chinh_RG'!F6 | G6: ='02. Nhap lieu tai chinh_RG'!G6 | H6: ='02. Nhap lieu tai chinh_RG'!H6
B7: Năm | D7: ='02. Nhap lieu tai chinh_RG'!D7 | E7: ='02. Nhap lieu tai chinh_RG'!E7 | F7: ='02. Nhap lieu tai chinh_RG'!F7 | G7: ='02. Nhap lieu tai chinh_RG'!G7 | H7: ='02. Nhap lieu tai chinh_RG'!H7
B8: Quý | D8: ='02. Nhap lieu tai chinh_RG'!D8 | E8: ='02. Nhap lieu tai chinh_RG'!E8 | F8: ='02. Nhap lieu tai chinh_RG'!F8 | G8: ='02. Nhap lieu tai chinh_RG'!G8 | H8: ='02. Nhap lieu tai chinh_RG'!H8
B9: Tháng | D9: ='02. Nhap lieu tai chinh_RG'!D9 | E9: ='02. Nhap lieu tai chinh_RG'!E9 | F9: ='02. Nhap lieu tai chinh_RG'!F9 | G9: ='02. Nhap lieu tai chinh_RG'!G9 | H9: ='02. Nhap lieu tai chinh_RG'!H9
B10: Đơn vị tính | D10: ='02. Nhap lieu tai chinh_RG'!D10 | E10: ='02. Nhap lieu tai chinh_RG'!E10 | F10: ='02. Nhap lieu tai chinh_RG'!F10 | G10: ='02. Nhap lieu tai chinh_RG'!G10 | H10: ='02. Nhap lieu tai chinh_RG'!H10
B11: TỔNG TÀI SẢN | D11: =D12+D13+D18+D25+D28+D31+D34+D35 | E11: =E12+E13+E18+E25+E28+E31+E34+E35 | F11: =F12+F13+F18+F25+F28+F31+F34+F35 | G11: =G12+G13+G18+G25+G28+G31+G34+G35 | H11: =H12+H13+H18+H25+H28+H31+H34+H35
B12: I. Tiền và các khoản tương đương tiền | D12: ='02. Nhap lieu tai chinh_RG'!D12 | E12: ='02. Nhap lieu tai chinh_RG'!E12 | F12: ='02. Nhap lieu tai chinh_RG'!F12 | G12: ='02. Nhap lieu tai chinh_RG'!G12 | H12: ='02. Nhap lieu tai chinh_RG'!H12
B13: II. Đầu tư tài chính | D13: =SUM(D14:D17) | E13: =SUM(E14:E17) | F13: =SUM(F14:F17) | G13: =SUM(G14:G17) | H13: =SUM(H14:H17)
B14: 1. Chứng khoán kinh doanh | D14: ='02. Nhap lieu tai chinh_RG'!D14 | E14: ='02. Nhap lieu tai chinh_RG'!E14 | F14: ='02. Nhap lieu tai chinh_RG'!F14 | G14: ='02. Nhap lieu tai chinh_RG'!G14 | H14: ='02. Nhap lieu tai chinh_RG'!H14
B15: 2. Đầu tư nắm giữ đến ngày đáo hạn | D15: ='02. Nhap lieu tai chinh_RG'!D15 | E15: ='02. Nhap lieu tai chinh_RG'!E15 | F15: ='02. Nhap lieu tai chinh_RG'!F15 | G15: ='02. Nhap lieu tai chinh_RG'!G15 | H15: ='02. Nhap lieu tai chinh_RG'!H15
B16: 3. Đầu tư góp vốn vào đơn vị khác | D16: ='02. Nhap lieu tai chinh_RG'!D16 | E16: ='02. Nhap lieu tai chinh_RG'!E16 | F16: ='02. Nhap lieu tai chinh_RG'!F16 | G16: ='02. Nhap lieu tai chinh_RG'!G16 | H16: ='02. Nhap lieu tai chinh_RG'!H16
B17: 4. Dự phòng tổn thất đầu tư tài chính (*) | D17: ='02. Nhap lieu tai chinh_RG'!D17 | E17: ='02. Nhap lieu tai chinh_RG'!E17 | F17: ='02. Nhap lieu tai chinh_RG'!F17 | G17: ='02. Nhap lieu tai chinh_RG'!G17 | H17: ='02. Nhap lieu tai chinh_RG'!H17
B18: III. Các khoản phải thu | D18: =SUM(D19:D24) | E18: =SUM(E19:E24) | F18: =SUM(F19:F24) | G18: =SUM(G19:G24) | H18: =SUM(H19:H24)
B19: 1. Phải thu của khách hàng | D19: ='02. Nhap lieu tai chinh_RG'!D19 | E19: ='02. Nhap lieu tai chinh_RG'!E19 | F19: ='02. Nhap lieu tai chinh_RG'!F19 | G19: ='02. Nhap lieu tai chinh_RG'!G19 | H19: ='02. Nhap lieu tai chinh_RG'!H19
B20: 2. Trả trước cho người bán | D20: ='02. Nhap lieu tai chinh_RG'!D20 | E20: ='02. Nhap lieu tai chinh_RG'!E20 | F20: ='02. Nhap lieu tai chinh_RG'!F20 | G20: ='02. Nhap lieu tai chinh_RG'!G20 | H20: ='02. Nhap lieu tai chinh_RG'!H20
B21: 3. Vốn kinh doanh ở đơn vị trực thuộc | D21: ='02. Nhap lieu tai chinh_RG'!D21 | E21: ='02. Nhap lieu tai chinh_RG'!E21 | F21: ='02. Nhap lieu tai chinh_RG'!F21 | G21: ='02. Nhap lieu tai chinh_RG'!G21 | H21: ='02. Nhap lieu tai chinh_RG'!H21
B22: 4. Phải thu khác | D22: ='02. Nhap lieu tai chinh_RG'!D22 | E22: ='02. Nhap lieu tai chinh_RG'!E22 | F22: ='02. Nhap lieu tai chinh_RG'!F22 | G22: ='02. Nhap lieu tai chinh_RG'!G22 | H22: ='02. Nhap lieu tai chinh_RG'!H22
B23: 5. Tài sản thiếu chờ xử lý | D23: ='02. Nhap lieu tai chinh_RG'!D23 | E23: ='02. Nhap lieu tai chinh_RG'!E23 | F23: ='02. Nhap lieu tai chinh_RG'!F23 | G23: ='02. Nhap lieu tai chinh_RG'!G23 | H23: ='02. Nhap lieu tai chinh_RG'!H23
B24: 6. Dự phòng phải thu khó đòi (*) | D24: ='02. Nhap lieu tai chinh_RG'!D24 | E24: ='02. Nhap lieu tai chinh_RG'!E24 | F24: ='02. Nhap lieu tai chinh_RG'!F24 | G24: ='02. Nhap lieu tai chinh_RG'!G24 | H24: ='02. Nhap lieu tai chinh_RG'!H24
B25: IV. Hàng tồn kho | D25: =SUM(D26:D27) | E25: =SUM(E26:E27) | F25: =SUM(F26:F27) | G25: =SUM(G26:G27) | H25: =SUM(H26:H27)
B26: 1. Hàng tồn kho | D26: ='02. Nhap lieu tai chinh_RG'!D26 | E26: ='02. Nhap lieu tai chinh_RG'!E26 | F26: ='02. Nhap lieu tai chinh_RG'!F26 | G26: ='02. Nhap lieu tai chinh_RG'!G26 | H26: ='02. Nhap lieu tai chinh_RG'!H26
B27: 2. Dự phòng giảm giả hàng tồn kho (*) | D27: ='02. Nhap lieu tai chinh_RG'!D27 | E27: ='02. Nhap lieu tai chinh_RG'!E27 | F27: ='02. Nhap lieu tai chinh_RG'!F27 | G27: ='02. Nhap lieu tai chinh_RG'!G27 | H27: ='02. Nhap lieu tai chinh_RG'!H27
B28: V. Tài sản cố định | D28: =SUM(D29:D30) | E28: =SUM(E29:E30) | F28: =SUM(F29:F30) | G28: =SUM(G29:G30) | H28: =SUM(H29:H30)
B29: - Nguyên giá | D29: ='02. Nhap lieu tai chinh_RG'!D29 | E29: ='02. Nhap lieu tai chinh_RG'!E29 | F29: ='02. Nhap lieu tai chinh_RG'!F29 | G29: ='02. Nhap lieu tai chinh_RG'!G29 | H29: ='02. Nhap lieu tai chinh_RG'!H29
B30: - Giá trị hao mòn lũy kế | D30: ='02. Nhap lieu tai chinh_RG'!D30 | E30: ='02. Nhap lieu tai chinh_RG'!E30 | F30: ='02. Nhap lieu tai chinh_RG'!F30 | G30: ='02. Nhap lieu tai chinh_RG'!G30 | H30: ='02. Nhap lieu tai chinh_RG'!H30
B31: VI. Bất động sản đầu tư | D31: =SUM(D32:D33) | E31: =SUM(E32:E33) | F31: =SUM(F32:F33) | G31: =SUM(G32:G33) | H31: =SUM(H32:H33)
B32: - Nguyên giá | D32: ='02. Nhap lieu tai chinh_RG'!D32 | E32: ='02. Nhap lieu tai chinh_RG'!E32 | F32: ='02. Nhap lieu tai chinh_RG'!F32 | G32: ='02. Nhap lieu tai chinh_RG'!G32 | H32: ='02. Nhap lieu tai chinh_RG'!H32
B33: - Giá trị hao mòn lũy kế (*) | D33: ='02. Nhap lieu tai chinh_RG'!D33 | E33: ='02. Nhap lieu tai chinh_RG'!E33 | F33: ='02. Nhap lieu tai chinh_RG'!F33 | G33: ='02. Nhap lieu tai chinh_RG'!G33 | H33: ='02. Nhap lieu tai chinh_RG'!H33
B34: VII. XDCB dở dang | D34: ='02. Nhap lieu tai chinh_RG'!D34 | E34: ='02. Nhap lieu tai chinh_RG'!E34 | F34: ='02. Nhap lieu tai chinh_RG'!F34 | G34: ='02. Nhap lieu tai chinh_RG'!G34 | H34: ='02. Nhap lieu tai chinh_RG'!H34
B35: VIII. Tài sản khác | D35: =SUM(D36:D37) | E35: =SUM(E36:E37) | F35: =SUM(F36:F37) | G35: =SUM(G36:G37) | H35: =SUM(H36:H37)
B36: 1. Thuế GTGT được khấu trừ | D36: ='02. Nhap lieu tai chinh_RG'!D36 | E36: ='02. Nhap lieu tai chinh_RG'!E36 | F36: ='02. Nhap lieu tai chinh_RG'!F36 | G36: ='02. Nhap lieu tai chinh_RG'!G36 | H36: ='02. Nhap lieu tai chinh_RG'!H36
B37: 2. Tài sản khác | D37: ='02. Nhap lieu tai chinh_RG'!D37 | E37: ='02. Nhap lieu tai chinh_RG'!E37 | F37: ='02. Nhap lieu tai chinh_RG'!F37 | G37: ='02. Nhap lieu tai chinh_RG'!G37 | H37: ='02. Nhap lieu tai chinh_RG'!H37
B38: TỔNG NGUỒN VỐN | D38: =D39+D50 | E38: =E39+E50 | F38: =F39+F50 | G38: =G39+G50 | H38: =H39+H50
B39: I. Nợ phải trả | D39: =SUM(D40:D49) | E39: =SUM(E40:E49) | F39: =SUM(F40:F49) | G39: =SUM(G40:G49) | H39: =SUM(H40:H49)
B40: 1. Phải trả người bán | D40: ='02. Nhap lieu tai chinh_RG'!D40 | E40: ='02. Nhap lieu tai chinh_RG'!E40 | F40: ='02. Nhap lieu tai chinh_RG'!F40 | G40: ='02. Nhap lieu tai chinh_RG'!G40 | H40: ='02. Nhap lieu tai chinh_RG'!H40
...

Sheet 06. Phan tich tai chinh_RG
J1: MSB
D2: =IF('01. Thong tin chung'!B9="Đầy đủ",IF(ISBLANK('06. Phan tich tai chinh_DD'!B9),0,'06. Phan tich tai chinh_DD'!B9),IF(ISBLANK('06. Phan tich tai chinh_RG'!B9),0,'06. Phan tich tai chinh_RG'!B9)) | J2: TNR Tower, 54A Nguyễn Chí Thanh, Đống Đa, Hà Nội
A4: PHỤ LỤC: PHÂN TÍCH TÀI CHÍNH
A5: (Kèm theo Tờ trình số ngày / / )
A7: ='01. Thong tin chung'!B3 | B7: ='03. Dulieutaichinhlamsach_RG'!D5 | C7: ='03. Dulieutaichinhlamsach_RG'!E5 | D7: ='03. Dulieutaichinhlamsach_RG'!F5 | G7: ='03. Dulieutaichinhlamsach_RG'!G5 | I7: ="Dự kiến năm "&'03. Dulieutaichinhlamsach_RG'!F5+1 | J7: Nội dung phân tích (nếu có)
A8: ="Đơn vị tính: "&'01. Thong tin chung'!B6 | B8: =IF(OR(B9-B36>1,B9-B36<-1),"Chưa cân số","") | C8: =IF(OR(C9-C36>1,C9-C36<-1),"Chưa cân số","") | D8: =IF(OR(D9-D36>1,D9-D36<-1),"Chưa cân số","") | E8: Tỷ trọng | F8: Tăng trưởng | G8: =IF(OR(G9-G36>1,G9-G36<-1),"Chưa cân số","") | H8: Tỷ trọng | I8: =IF(OR(I9-I36>1,I9-I36<-1),"Chưa cân số","")
A9: TỔNG TÀI SẢN | B9: =B10+B11+B16+B23+B26+B32+B33 | C9: =C10+C11+C16+C23+C26+C32+C33 | D9: =D10+D11+D16+D23+D26+D32+D33 | E9: =IF($D$9<>0,D9/$D$9,"") | F9: =IF(C9<>0,(D9-C9)/C9,"") | G9: =G10+G11+G16+G23+G26+G32+G33 | H9: =IF($G$9<>0,G9/$G$9,"") | I9: =I10+I11+I16+I23+I26+I32+I33
A10: I. Tiền và các khoản tương đương tiền | B10: =IF(TRIM('03. Dulieutaichinhlamsach_RG'!$G$2)="VND",'03. Dulieutaichinhlamsach_RG'!D12/10^6,'03. Dulieutaichinhlamsach_RG'!D12) | C10: =IF(TRIM('03. Dulieutaichinhlamsach_RG'!$G$2)="VND",'03. Dulieutaichinhlamsach_RG'!E12/10^6,'03. Dulieutaichinhlamsach_RG'!E12) | D10: =IF(TRIM('03. Dulieutaichinhlamsach_RG'!$G$2)="VND",'03. Dulieutaichinhlamsach_RG'!F12/10^6,'03. Dulieutaichinhlamsach_RG'!F12) | E10: =IF($D$9<>0,D10/$D$9,"") | F10: =IF(C10<>0,(D10-C10)/C10,"") | G10: =IF(TRIM('03. Dulieutaichinhlamsach_RG'!$G$2)="VND",'03. Dulieutaichinhlamsach_RG'!I12/10^6,'03. Dulieutaichinhlamsach_RG'!I12) | H10: =IF($G$9<>0,G10/$G$9,"") | I10: =IF(TRIM('03. Dulieutaichinhlamsach_RG'!$G$2)="VND",'03. Dulieutaichinhlamsach_RG'!K12/10^6,'03. Dulieutaichinhlamsach_RG'!K12)
A11: II. Đầu tư tài chính | B11: =SUM(B12:B15) | C11: =SUM(C12:C15) | D11: =SUM(D12:D15) | E11: =IF($D$9<>0,D11/$D$9,"") | F11: =IF(C11<>0,(D11-C11)/C11,"") | G11: =SUM(G12:G15) | H11: =IF($G$10<>0,G11/$G$10," ") | I11: =SUM(I12:I15)
A12: 1. Chứng khoán kinh doanh | B12: =IF(TRIM('03. Dulieutaichinhlamsach_RG'!$G$2)="VND",'03. Dulieutaichinhlamsach_RG'!D14/10^6,'03. Dulieutaichinhlamsach_RG'!D14) | C12: =IF(TRIM('03. Dulieutaichinhlamsach_RG'!$G$2)="VND",'03. Dulieutaichinhlamsach_RG'!E14/10^6,'03. Dulieutaichinhlamsach_RG'!E14) | D12: =IF(TRIM('03. Dulieutaichinhlamsach_RG'!$G$2)="VND",'03. Dulieutaichinhlamsach_RG'!F14/10^6,'03. Dulieutaichinhlamsach_RG'!F14) | E12: =IF($D$9<>0,D12/$D$9,"") | F12: =IF(C12<>0,(D12-C12)/C12,"") | G12: =IF(TRIM('03. Dulieutaichinhlamsach_RG'!$G$2)="VND",'03. Dulieutaichinhlamsach_RG'!I14/10^6,'03. Dulieutaichinhlamsach_RG'!I14) | H12: =IF($G$10<>0,G12/$G$10," ") | I12: =IF(TRIM('03. Dulieutaichinhlamsach_RG'!$G$2)="VND",'03. Dulieutaichinhlamsach_RG'!H14/10^6,'03. Dulieutaichinhlamsach_RG'!H14)
A13: 2. Đầu tư nắm giữ đến ngày đáo hạn | B13: =IF(TRIM('03. Dulieutaichinhlamsach_RG'!$G$2)="VND",'03. Dulieutaichinhlamsach_RG'!D15/10^6,'03. Dulieutaichinhlamsach_RG'!D15) | C13: =IF(TRIM('03. Dulieutaichinhlamsach_RG'!$G$2)="VND",'03. Dulieutaichinhlamsach_RG'!E15/10^6,'03. Dulieutaichinhlamsach_RG'!E15) | D13: =IF(TRIM('03. Dulieutaichinhlamsach_RG'!$G$2)="VND",'03. Dulieutaichinhlamsach_RG'!F15/10^6,'03. Dulieutaichinhlamsach_RG'!F15) | E13: =IF($D$9<>0,D13/$D$9,"") | F13: =IF(C13<>0,(D13-C13)/C13,"") | G13: =IF(TRIM('03. Dulieutaichinhlamsach_RG'!$G$2)="VND",'03. Dulieutaichinhlamsach_RG'!I15/10^6,'03. Dulieutaichinhlamsach_RG'!I15) | H13: =IF($G$10<>0,G13/$G$10," ") | I13: =IF(TRIM('03. Dulieutaichinhlamsach_RG'!$G$2)="VND",'03. Dulieutaichinhlamsach_RG'!H15/10^6,'03. Dulieutaichinhlamsach_RG'!H15)
A14: 3. Đầu tư góp vốn vào đơn vị khác | B14: =IF(TRIM('03. Dulieutaichinhlamsach_RG'!$G$2)="VND",'03. Dulieutaichinhlamsach_RG'!D16/10^6,'03. Dulieutaichinhlamsach_RG'!D16) | C14: =IF(TRIM('03. Dulieutaichinhlamsach_RG'!$G$2)="VND",'03. Dulieutaichinhlamsach_RG'!E16/10^6,'03. Dulieutaichinhlamsach_RG'!E16) | D14: =IF(TRIM('03. Dulieutaichinhlamsach_RG'!$G$2)="VND",'03. Dulieutaichinhlamsach_RG'!F16/10^6,'03. Dulieutaichinhlamsach_RG'!F16) | E14: =IF($D$9<>0,D14/$D$9,"") | F14: =IF(C14<>0,(D14-C14)/C14,"") | G14: =IF(TRIM('03. Dulieutaichinhlamsach_RG'!$G$2)="VND",'03. Dulieutaichinhlamsach_RG'!I16/10^6,'03. Dulieutaichinhlamsach_RG'!I16) | H14: =IF($G$10<>0,G14/$G$10," ") | I14: =IF(TRIM('03. Dulieutaichinhlamsach_RG'!$G$2)="VND",'03. Dulieutaichinhlamsach_RG'!H16/10^6,'03. Dulieutaichinhlamsach_RG'!H16)
A15: 4. Dự phòng tổn thất đầu tư tài chính (*) | B15: =IF(TRIM('03. Dulieutaichinhlamsach_RG'!$G$2)="VND",'03. Dulieutaichinhlamsach_RG'!D17/10^6,'03. Dulieutaichinhlamsach_RG'!D17) | C15: =IF(TRIM('03. Dulieutaichinhlamsach_RG'!$G$2)="VND",'03. Dulieutaichinhlamsach_RG'!E17/10^6,'03. Dulieutaichinhlamsach_RG'!E17) | D15: =IF(TRIM('03. Dulieutaichinhlamsach_RG'!$G$2)="VND",'03. Dulieutaichinhlamsach_RG'!F17/10^6,'03. Dulieutaichinhlamsach_RG'!F17) | E15: =IF($D$9<>0,D15/$D$9,"") | F15: =IF(C15<>0,(D15-C15)/C15,"") | G15: =IF(TRIM('03. Dulieutaichinhlamsach_RG'!$G$2)="VND",'03. Dulieutaichinhlamsach_RG'!I17/10^6,'03. Dulieutaichinhlamsach_RG'!I17) | H15: =IF($G$10<>0,G15/$G$10," ") | I15: =IF(TRIM('03. Dulieutaichinhlamsach_RG'!$G$2)="VND",'03. Dulieutaichinhlamsach_RG'!H17/10^6,'03. Dulieutaichinhlamsach_RG'!H17)
A16: III. Các khoản phải thu | B16: =SUM(B17:B22) | C16: =SUM(C17:C22) | D16: =SUM(D17:D22) | E16: =IF($D$10<>0,D16/$D$10," ") | F16: =IF(C16<>0,(D16-C16)/C16,"") | G16: =SUM(G17:G22) | H16: =IF($G$10<>0,G16/$G$10," ") | I16: =IF(TRIM('03. Dulieutaichinhlamsach_RG'!$G$2)="VND",'03. Dulieutaichinhlamsach_RG'!H18/10^6,'03. Dulieutaichinhlamsach_RG'!H18)
A17: 1. Phải thu của khách hàng | B17: =IF(TRIM('03. Dulieutaichinhlamsach_RG'!$G$2)="VND",'03. Dulieutaichinhlamsach_RG'!D19/10^6,'03. Dulieutaichinhlamsach_RG'!D19) | C17: =IF(TRIM('03. Dulieutaichinhlamsach_RG'!$G$2)="VND",'03. Dulieutaichinhlamsach_RG'!E19/10^6,'03. Dulieutaichinhlamsach_RG'!E19) | D17: =IF(TRIM('03. Dulieutaichinhlamsach_RG'!$G$2)="VND",'03. Dulieutaichinhlamsach_RG'!F19/10^6,'03. Dulieutaichinhlamsach_RG'!F19) | E17: =IF($D$10<>0,D17/$D$10," ") | F17: =IF(C17<>0,(D17-C17)/C17,"") | G17: =IF(TRIM('03. Dulieutaichinhlamsach_RG'!$G$2)="VND",'03. Dulieutaichinhlamsach_RG'!I19/10^6,'03. Dulieutaichinhlamsach_RG'!I19) | H17: =IF($G$10<>0,G17/$G$10," ") | I17: =IF(TRIM('03. Dulieutaichinhlamsach_RG'!$G$2)="VND",'03. Dulieutaichinhlamsach_RG'!K19/10^6,'03. Dulieutaichinhlamsach_RG'!K19)
A18: 2. Trả trước cho người bán | B18: =IF(TRIM('03. Dulieutaichinhlamsach_RG'!$G$2)="VND",'03. Dulieutaichinhlamsach_RG'!D20/10^6,'03. Dulieutaichinhlamsach_RG'!D20) | C18: =IF(TRIM('03. Dulieutaichinhlamsach_RG'!$G$2)="VND",'03. Dulieutaichinhlamsach_RG'!E20/10^6,'03. Dulieutaichinhlamsach_RG'!E20) | D18: =IF(TRIM('03. Dulieutaichinhlamsach_RG'!$G$2)="VND",'03. Dulieutaichinhlamsach_RG'!F20/10^6,'03. Dulieutaichinhlamsach_RG'!F20) | E18: =IF($D$10<>0,D18/$D$10," ") | F18: =IF(C18<>0,(D18-C18)/C18,"") | G18: =IF(TRIM('03. Dulieutaichinhlamsach_RG'!$G$2)="VND",'03. Dulieutaichinhlamsach_RG'!I20/10^6,'03. Dulieutaichinhlamsach_RG'!I20) | H18: =IF($G$10<>0,G18/$G$10," ") | I18: =IF(TRIM('03. Dulieutaichinhlamsach_RG'!$G$2)="VND",'03. Dulieutaichinhlamsach_RG'!K20/10^6,'03. Dulieutaichinhlamsach_RG'!K20)
A19: 3. Vốn kinh doanh ở đơn vị trực thuộc | B19: =IF(TRIM('03. Dulieutaichinhlamsach_RG'!$G$2)="VND",'03. Dulieutaichinhlamsach_RG'!D21/10^6,'03. Dulieutaichinhlamsach_RG'!D21) | C19: =IF(TRIM('03. Dulieutaichinhlamsach_RG'!$G$2)="VND",'03. Dulieutaichinhlamsach_RG'!E21/10^6,'03. Dulieutaichinhlamsach_RG'!E21) | D19: =IF(TRIM('03. Dulieutaichinhlamsach_RG'!$G$2)="VND",'03. Dulieutaichinhlamsach_RG'!F21/10^6,'03. Dulieutaichinhlamsach_RG'!F21) | E19: =IF($D$10<>0,D19/$D$10," ") | F19: =IF(C19<>0,(D19-C19)/C19,"") | G19: =IF(TRIM('03. Dulieutaichinhlamsach_RG'!$G$2)="VND",'03. Dulieutaichinhlamsach_RG'!I21/10^6,'03. Dulieutaichinhlamsach_RG'!I21) | H19: =IF($G$10<>0,G19/$G$10," ") | I19: =IF(TRIM('03. Dulieutaichinhlamsach_RG'!$G$2)="VND",'03. Dulieutaichinhlamsach_RG'!K21/10^6,'03. Dulieutaichinhlamsach_RG'!K21)
A20: 4. Phải thu khác | B20: =IF(TRIM('03. Dulieutaichinhlamsach_RG'!$G$2)="VND",'03. Dulieutaichinhlamsach_RG'!D22/10^6,'03. Dulieutaichinhlamsach_RG'!D22) | C20: =IF(TRIM('03. Dulieutaichinhlamsach_RG'!$G$2)="VND",'03. Dulieutaichinhlamsach_RG'!E22/10^6,'03. Dulieutaichinhlamsach_RG'!E22) | D20: =IF(TRIM('03. Dulieutaichinhlamsach_RG'!$G$2)="VND",'03. Dulieutaichinhlamsach_RG'!F22/10^6,'03. Dulieutaichinhlamsach_RG'!F22) | E20: =IF($D$10<>0,D20/$D$10," ") | F20: =IF(C20<>0,(D20-C20)/C20,"") | G20: =IF(TRIM('03. Dulieutaichinhlamsach_RG'!$G$2)="VND",'03. Dulieutaichinhlamsach_RG'!I22/10^6,'03. Dulieutaichinhlamsach_RG'!I22) | H20: =IF($G$10<>0,G20/$G$10," ") | I20: =IF(TRIM('03. Dulieutaichinhlamsach_RG'!$G$2)="VND",'03. Dulieutaichinhlamsach_RG'!K22/10^6,'03. Dulieutaichinhlamsach_RG'!K22)
A21: 5. Tài sản thiếu chờ xử lý | B21: =IF(TRIM('03. Dulieutaichinhlamsach_RG'!$G$2)="VND",'03. Dulieutaichinhlamsach_RG'!D23/10^6,'03. Dulieutaichinhlamsach_RG'!D23) | C21: =IF(TRIM('03. Dulieutaichinhlamsach_RG'!$G$2)="VND",'03. Dulieutaichinhlamsach_RG'!E23/10^6,'03. Dulieutaichinhlamsach_RG'!E23) | D21: =IF(TRIM('03. Dulieutaichinhlamsach_RG'!$G$2)="VND",'03. Dulieutaichinhlamsach_RG'!F23/10^6,'03. Dulieutaichinhlamsach_RG'!F23) | E21: =IF($D$10<>0,D21/$D$10," ") | F21: =IF(C21<>0,(D21-C21)/C21,"") | G21: =IF(TRIM('03. Dulieutaichinhlamsach_RG'!$G$2)="VND",'03. Dulieutaichinhlamsach_RG'!I23/10^6,'03. Dulieutaichinhlamsach_RG'!I23) | H21: =IF($G$10<>0,G21/$G$10," ") | I21: =IF(TRIM('03. Dulieutaichinhlamsach_RG'!$G$2)="VND",'03. Dulieutaichinhlamsach_RG'!K23/10^6,'03. Dulieutaichinhlamsach_RG'!K23)
A22: 6. Dự phòng phải thu khó đòi (*) | B22: =IF(TRIM('03. Dulieutaichinhlamsach_RG'!$G$2)="VND",'03. Dulieutaichinhlamsach_RG'!D24/10^6,'03. Dulieutaichinhlamsach_RG'!D24) | C22: =IF(TRIM('03. Dulieutaichinhlamsach_RG'!$G$2)="VND",'03. Dulieutaichinhlamsach_RG'!E24/10^6,'03. Dulieutaichinhlamsach_RG'!E24) | D22: =IF(TRIM('03. Dulieutaichinhlamsach_RG'!$G$2)="VND",'03. Dulieutaichinhlamsach_RG'!F24/10^6,'03. Dulieutaichinhlamsach_RG'!F24) | E22: =IF($D$10<>0,D22/$D$10," ") | F22: =IF(C22<>0,(D22-C22)/C22,"") | G22: =IF(TRIM('03. Dulieutaichinhlamsach_RG'!$G$2)="VND",'03. Dulieutaichinhlamsach_RG'!I24/10^6,'03. Dulieutaichinhlamsach_RG'!I24) | H22: =IF($G$10<>0,G22/$G$10," ") | I22: =IF(TRIM('03. Dulieutaichinhlamsach_RG'!$G$2)="VND",'03. Dulieutaichinhlamsach_RG'!K24/10^6,'03. Dulieutaichinhlamsach_RG'!K24)
A23: IV. Hàng tồn kho | B23: =SUM(B24:B25) | C23: =SUM(C24:C25) | D23: =SUM(D24:D25) | E23: =IF($D$10<>0,D23/$D$10," ") | F23: =IF(C23<>0,(D23-C23)/C23,"") | G23: =IF(TRIM('03. Dulieutaichinhlamsach_RG'!$G$2)="VND",'03. Dulieutaichinhlamsach_RG'!I25/10^6,'03. Dulieutaichinhlamsach_RG'!I25) | H23: =IF($G$10<>0,G23/$G$10," ") | I23: =IF(TRIM('03. Dulieutaichinhlamsach_RG'!$G$2)="VND",'03. Dulieutaichinhlamsach_RG'!K25/10^6,'03. Dulieutaichinhlamsach_RG'!K25)
A24: 1. Hàng tồn kho | B24: =IF(TRIM('03. Dulieutaichinhlamsach_RG'!$G$2)="VND",'03. Dulieutaichinhlamsach_RG'!D26/10^6,'03. Dulieutaichinhlamsach_RG'!D26) | C24: =IF(TRIM('03. Dulieutaichinhlamsach_RG'!$G$2)="VND",'03. Dulieutaichinhlamsach_RG'!E26/10^6,'03. Dulieutaichinhlamsach_RG'!E26) | D24: =IF(TRIM('03. Dulieutaichinhlamsach_RG'!$G$2)="VND",'03. Dulieutaichinhlamsach_RG'!F26/10^6,'03. Dulieutaichinhlamsach_RG'!F26) | E24: =IF($D$10<>0,D24/$D$10," ") | F24: =IF(C24<>0,(D24-C24)/C24,"") | G24: =IF(TRIM('03. Dulieutaichinhlamsach_RG'!$G$2)="VND",'03. Dulieutaichinhlamsach_RG'!I26/10^6,'03. Dulieutaichinhlamsach_RG'!I26) | H24: =IF($G$10<>0,G24/$G$10," ") | I24: =IF(TRIM('03. Dulieutaichinhlamsach_RG'!$G$2)="VND",'03. Dulieutaichinhlamsach_RG'!K26/10^6,'03. Dulieutaichinhlamsach_RG'!K26)
A25: 2. Dự phòng giảm giả hàng tồn kho (*) | B25: =IF(TRIM('03. Dulieutaichinhlamsach_RG'!$G$2)="VND",'03. Dulieutaichinhlamsach_RG'!D27/10^6,'03. Dulieutaichinhlamsach_RG'!D27) | C25: =IF(TRIM('03. Dulieutaichinhlamsach_RG'!$G$2)="VND",'03. Dulieutaichinhlamsach_RG'!E27/10^6,'03. Dulieutaichinhlamsach_RG'!E27) | D25: =IF(TRIM('03. Dulieutaichinhlamsach_RG'!$G$2)="VND",'03. Dulieutaichinhlamsach_RG'!F27/10^6,'03. Dulieutaichinhlamsach_RG'!F27) | E25: =IF($D$10<>0,D25/$D$10," ") | F25: =IF(C25<>0,(D25-C25)/C25,"") | G25: =IF(TRIM('03. Dulieutaichinhlamsach_RG'!$G$2)="VND",'03. Dulieutaichinhlamsach_RG'!I27/10^6,'03. Dulieutaichinhlamsach_RG'!I27) | H25: =IF($G$10<>0,G25/$G$10," ") | I25: =IF(TRIM('03. Dulieutaichinhlamsach_RG'!$G$2)="VND",'03. Dulieutaichinhlamsach_RG'!K27/10^6,'03. Dulieutaichinhlamsach_RG'!K27)
A26: V. Tài sản cố định | B26: =SUM(B27:B28) | C26: =SUM(C27:C28) | D26: =SUM(D27:D28) | E26: =IF($D$10<>0,D26/$D$10," ") | F26: =IF(C26<>0,(D26-C26)/C26,"") | G26: =IF(TRIM('03. Dulieutaichinhlamsach_RG'!$G$2)="VND",'03. Dulieutaichinhlamsach_RG'!I28/10^6,'03. Dulieutaichinhlamsach_RG'!I28) | H26: =IF($G$10<>0,G26/$G$10," ") | I26: =IF(TRIM('03. Dulieutaichinhlamsach_RG'!$G$2)="VND",'03. Dulieutaichinhlamsach_RG'!K28/10^6,'03. Dulieutaichinhlamsach_RG'!K28)
A27: - Nguyên giá | B27: =IF(TRIM('03. Dulieutaichinhlamsach_RG'!$G$2)="VND",'03. Dulieutaichinhlamsach_RG'!D29/10^6,'03. Dulieutaichinhlamsach_RG'!D29) | C27: =IF(TRIM('03. Dulieutaichinhlamsach_RG'!$G$2)="VND",'03. Dulieutaichinhlamsach_RG'!E29/10^6,'03. Dulieutaichinhlamsach_RG'!E29) | D27: =IF(TRIM('03. Dulieutaichinhlamsach_RG'!$G$2)="VND",'03. Dulieutaichinhlamsach_RG'!F29/10^6,'03. Dulieutaichinhlamsach_RG'!F29) | E27: =IF($D$10<>0,D27/$D$10," ") | F27: =IF(C27<>0,(D27-C27)/C27,"") | G27: =IF(TRIM('03. Dulieutaichinhlamsach_RG'!$G$2)="VND",'03. Dulieutaichinhlamsach_RG'!I29/10^6,'03. Dulieutaichinhlamsach_RG'!I29) | H27: =IF($G$10<>0,G27/$G$10," ") | I27: =IF(TRIM('03. Dulieutaichinhlamsach_RG'!$G$2)="VND",'03. Dulieutaichinhlamsach_RG'!K29/10^6,'03. Dulieutaichinhlamsach_RG'!K29)
A28: - Giá trị hao mòn lũy kế | B28: =IF(TRIM('03. Dulieutaichinhlamsach_RG'!$G$2)="VND",'03. Dulieutaichinhlamsach_RG'!D30/10^6,'03. Dulieutaichinhlamsach_RG'!D30) | C28: =IF(TRIM('03. Dulieutaichinhlamsach_RG'!$G$2)="VND",'03. Dulieutaichinhlamsach_RG'!E30/10^6,'03. Dulieutaichinhlamsach_RG'!E30) | D28: =IF(TRIM('03. Dulieutaichinhlamsach_RG'!$G$2)="VND",'03. Dulieutaichinhlamsach_RG'!F30/10^6,'03. Dulieutaichinhlamsach_RG'!F30) | E28: =IF($D$10<>0,D28/$D$10," ") | F28: =IF(C28<>0,(D28-C28)/C28,"") | G28: =IF(TRIM('03. Dulieutaichinhlamsach_RG'!$G$2)="VND",'03. Dulieutaichinhlamsach_RG'!I30/10^6,'03. Dulieutaichinhlamsach_RG'!I30) | H28: =IF($G$10<>0,G28/$G$10," ") | I28: =IF(TRIM('03. Dulieutaichinhlamsach_RG'!$G$2)="VND",'03. Dulieutaichinhlamsach_RG'!K30/10^6,'03. Dulieutaichinhlamsach_RG'!K30)
A29: VI. Bất động sản đầu tư | B29: =SUM(B30:B31) | C29: =SUM(C30:C31) | D29: =SUM(D30:D31) | E29: =IF($D$10<>0,D29/$D$10," ") | F29: =IF(C29<>0,(D29-C29)/C29,"") | G29: =IF(TRIM('03. Dulieutaichinhlamsach_RG'!$G$2)="VND",'03. Dulieutaichinhlamsach_RG'!I31/10^6,'03. Dulieutaichinhlamsach_RG'!I31) | H29: =IF($G$10<>0,G29/$G$10," ") | I29: =IF(TRIM('03. Dulieutaichinhlamsach_RG'!$G$2)="VND",'03. Dulieutaichinhlamsach_RG'!K31/10^6,'03. Dulieutaichinhlamsach_RG'!K31)
A30: - Nguyên giá | B30: =IF(TRIM('03. Dulieutaichinhlamsach_RG'!$G$2)="VND",'03. Dulieutaichinhlamsach_RG'!D32/10^6,'03. Dulieutaichinhlamsach_RG'!D32) | C30: =IF(TRIM('03. Dulieutaichinhlamsach_RG'!$G$2)="VND",'03. Dulieutaichinhlamsach_RG'!E32/10^6,'03. Dulieutaichinhlamsach_RG'!E32) | D30: =IF(TRIM('03. Dulieutaichinhlamsach_RG'!$G$2)="VND",'03. Dulieutaichinhlamsach_RG'!F32/10^6,'03. Dulieutaichinhlamsach_RG'!F32) | E30: =IF($D$10<>0,D30/$D$10," ") | F30: =IF(C30<>0,(D30-C30)/C30,"") | G30: =IF(TRIM('03. Dulieutaichinhlamsach_RG'!$G$2)="VND",'03. Dulieutaichinhlamsach_RG'!I32/10^6,'03. Dulieutaichinhlamsach_RG'!I32) | H30: =IF($G$10<>0,G30/$G$10," ") | I30: =IF(TRIM('03. Dulieutaichinhlamsach_RG'!$G$2)="VND",'03. Dulieutaichinhlamsach_RG'!K32/10^6,'03. Dulieutaichinhlamsach_RG'!K32)
A31: - Giá trị hao mòn lũy kế (*) | B31: =IF(TRIM('03. Dulieutaichinhlamsach_RG'!$G$2)="VND",'03. Dulieutaichinhlamsach_RG'!D33/10^6,'03. Dulieutaichinhlamsach_RG'!D33) | C31: =IF(TRIM('03. Dulieutaichinhlamsach_RG'!$G$2)="VND",'03. Dulieutaichinhlamsach_RG'!E33/10^6,'03. Dulieutaichinhlamsach_RG'!E33) | D31: =IF(TRIM('03. Dulieutaichinhlamsach_RG'!$G$2)="VND",'03. Dulieutaichinhlamsach_RG'!F33/10^6,'03. Dulieutaichinhlamsach_RG'!F33) | E31: =IF($D$10<>0,D31/$D$10," ") | F31: =IF(C31<>0,(D31-C31)/C31,"") | G31: =IF(TRIM('03. Dulieutaichinhlamsach_RG'!$G$2)="VND",'03. Dulieutaichinhlamsach_RG'!I33/10^6,'03. Dulieutaichinhlamsach_RG'!I33) | H31: =IF($G$10<>0,G31/$G$10," ") | I31: =IF(TRIM('03. Dulieutaichinhlamsach_RG'!$G$2)="VND",'03. Dulieutaichinhlamsach_RG'!K33/10^6,'03. Dulieutaichinhlamsach_RG'!K33)
A32: VII. XDCB dở dang | B32: =IF(TRIM('03. Dulieutaichinhlamsach_RG'!$G$2)="VND",'03. Dulieutaichinhlamsach_RG'!D34/10^6,'03. Dulieutaichinhlamsach_RG'!D34) | C32: =IF(TRIM('03. Dulieutaichinhlamsach_RG'!$G$2)="VND",'03. Dulieutaichinhlamsach_RG'!E34/10^6,'03. Dulieutaichinhlamsach_RG'!E34) | D32: =IF(TRIM('03. Dulieutaichinhlamsach_RG'!$G$2)="VND",'03. Dulieutaichinhlamsach_RG'!F34/10^6,'03. Dulieutaichinhlamsach_RG'!F34) | E32: =IF($D$10<>0,D32/$D$10," ") | F32: =IF(C32<>0,(D32-C32)/C32,"") | G32: =IF(TRIM('03. Dulieutaichinhlamsach_RG'!$G$2)="VND",'03. Dulieutaichinhlamsach_RG'!I34/10^6,'03. Dulieutaichinhlamsach_RG'!I34) | H32: =IF($G$10<>0,G32/$G$10," ") | I32: =IF(TRIM('03. Dulieutaichinhlamsach_RG'!$G$2)="VND",'03. Dulieutaichinhlamsach_RG'!K34/10^6,'03. Dulieutaichinhlamsach_RG'!K34)
A33: VIII. Tài sản khác | B33: =SUM(B34:B35) | C33: =SUM(C34:C35) | D33: =SUM(D34:D35) | E33: =IF($D$10<>0,D33/$D$10," ") | F33: =IF(C33<>0,(D33-C33)/C33,"") | G33: =IF(TRIM('03. Dulieutaichinhlamsach_RG'!$G$2)="VND",'03. Dulieutaichinhlamsach_RG'!I35/10^6,'03. Dulieutaichinhlamsach_RG'!I35) | H33: =IF($G$10<>0,G33/$G$10," ") | I33: =IF(TRIM('03. Dulieutaichinhlamsach_RG'!$G$2)="VND",'03. Dulieutaichinhlamsach_RG'!K35/10^6,'03. Dulieutaichinhlamsach_RG'!K35)
A34: 1. Thuế GTGT được khấu trừ | B34: =IF(TRIM('03. Dulieutaichinhlamsach_RG'!$G$2)="VND",'03. Dulieutaichinhlamsach_RG'!D36/10^6,'03. Dulieutaichinhlamsach_RG'!D36) | C34: =IF(TRIM('03. Dulieutaichinhlamsach_RG'!$G$2)="VND",'03. Dulieutaichinhlamsach_RG'!E36/10^6,'03. Dulieutaichinhlamsach_RG'!E36) | D34: =IF(TRIM('03. Dulieutaichinhlamsach_RG'!$G$2)="VND",'03. Dulieutaichinhlamsach_RG'!F36/10^6,'03. Dulieutaichinhlamsach_RG'!F36) | E34: =IF($D$10<>0,D34/$D$10," ") | F34: =IF(C34<>0,(D34-C34)/C34,"") | G34: =IF(TRIM('03. Dulieutaichinhlamsach_RG'!$G$2)="VND",'03. Dulieutaichinhlamsach_RG'!I36/10^6,'03. Dulieutaichinhlamsach_RG'!I36) | H34: =IF($G$10<>0,G34/$G$10," ") | I34: =IF(TRIM('03. Dulieutaichinhlamsach_RG'!$G$2)="VND",'03. Dulieutaichinhlamsach_RG'!K36/10^6,'03. Dulieutaichinhlamsach_RG'!K36)
A35: 2. Tài sản khác | B35: =IF(TRIM('03. Dulieutaichinhlamsach_RG'!$G$2)="VND",'03. Dulieutaichinhlamsach_RG'!D37/10^6,'03. Dulieutaichinhlamsach_RG'!D37) | C35: =IF(TRIM('03. Dulieutaichinhlamsach_RG'!$G$2)="VND",'03. Dulieutaichinhlamsach_RG'!E37/10^6,'03. Dulieutaichinhlamsach_RG'!E37) | D35: =IF(TRIM('03. Dulieutaichinhlamsach_RG'!$G$2)="VND",'03. Dulieutaichinhlamsach_RG'!F37/10^6,'03. Dulieutaichinhlamsach_RG'!F37) | E35: =IF($D$10<>0,D35/$D$10," ") | F35: =IF(C35<>0,(D35-C35)/C35,"") | G35: =IF(TRIM('03. Dulieutaichinhlamsach_RG'!$G$2)="VND",'03. Dulieutaichinhlamsach_RG'!I37/10^6,'03. Dulieutaichinhlamsach_RG'!I37) | H35: =IF($G$10<>0,G35/$G$10," ") | I35: =IF(TRIM('03. Dulieutaichinhlamsach_RG'!$G$2)="VND",'03. Dulieutaichinhlamsach_RG'!K37/10^6,'03. Dulieutaichinhlamsach_RG'!K37)
A36: TỔNG NGUỒN VỐN | B36: =IF(TRIM('03. Dulieutaichinhlamsach_RG'!$G$2)="VND",'03. Dulieutaichinhlamsach_RG'!D38/10^6,'03. Dulieutaichinhlamsach_RG'!D38) | C36: =IF(TRIM('03. Dulieutaichinhlamsach_RG'!$G$2)="VND",'03. Dulieutaichinhlamsach_RG'!E38/10^6,'03. Dulieutaichinhlamsach_RG'!E38) | D36: =IF(TRIM('03. Dulieutaichinhlamsach_RG'!$G$2)="VND",'03. Dulieutaichinhlamsach_RG'!F38/10^6,'03. Dulieutaichinhlamsach_RG'!F38) | E36: =IF($D$10<>0,D36/$D$10," ") | F36: =IF(C36<>0,(D36-C36)/C36,"") | G36: =IF(TRIM('03. Dulieutaichinhlamsach_RG'!$G$2)="VND",'03. Dulieutaichinhlamsach_RG'!I38/10^6,'03. Dulieutaichinhlamsach_RG'!I38) | H36: =IF($G$10<>0,G36/$G$10," ") | I36: =IF(TRIM('03. Dulieutaichinhlamsach_RG'!$G$2)="VND",'03. Dulieutaichinhlamsach_RG'!K38/10^6,'03. Dulieutaichinhlamsach_RG'!K38)
A37: I. Nợ phải trả | B37: =IF(TRIM('03. Dulieutaichinhlamsach_RG'!$G$2)="VND",'03. Dulieutaichinhlamsach_RG'!D39/10^6,'03. Dulieutaichinhlamsach_RG'!D39) | C37: =IF(TRIM('03. Dulieutaichinhlamsach_RG'!$G$2)="VND",'03. Dulieutaichinhlamsach_RG'!E39/10^6,'03. Dulieutaichinhlamsach_RG'!E39) | D37: =IF(TRIM('03. Dulieutaichinhlamsach_RG'!$G$2)="VND",'03. Dulieutaichinhlamsach_RG'!F39/10^6,'03. Dulieutaichinhlamsach_RG'!F39) | E37: =IF($D$10<>0,D37/$D$10," ") | F37: =IF(C37<>0,(D37-C37)/C37,"") | G37: =IF(TRIM('03. Dulieutaichinhlamsach_RG'!$G$2)="VND",'03. Dulieutaichinhlamsach_RG'!I39/10^6,'03. Dulieutaichinhlamsach_RG'!I39) | H37: =IF($G$10<>0,G37/$G$10," ") | I37: =IF(TRIM('03. Dulieutaichinhlamsach_RG'!$G$2)="VND",'03. Dulieutaichinhlamsach_RG'!K39/10^6,'03. Dulieutaichinhlamsach_RG'!K39)
A38: 1. Phải trả người bán | B38: =IF(TRIM('03. Dulieutaichinhlamsach_RG'!$G$2)="VND",'03. Dulieutaichinhlamsach_RG'!D40/10^6,'03. Dulieutaichinhlamsach_RG'!D40) | C38: =IF(TRIM('03. Dulieutaichinhlamsach_RG'!$G$2)="VND",'03. Dulieutaichinhlamsach_RG'!E40/10^6,'03. Dulieutaichinhlamsach_RG'!E40) | D38: =IF(TRIM('03. Dulieutaichinhlamsach_RG'!$G$2)="VND",'03. Dulieutaichinhlamsach_RG'!F40/10^6,'03. Dulieutaichinhlamsach_RG'!F40) | E38: =IF($D$10<>0,D38/$D$10," ") | F38: =IF(C38<>0,(D38-C38)/C38,"") | G38: =IF(TRIM('03. Dulieutaichinhlamsach_RG'!$G$2)="VND",'03. Dulieutaichinhlamsach_RG'!I40/10^6,'03. Dulieutaichinhlamsach_RG'!I40) | H38: =IF($G$10<>0,G38/$G$10," ") | I38: =IF(TRIM('03. Dulieutaichinhlamsach_RG'!$G$2)="VND",'03. Dulieutaichinhlamsach_RG'!K40/10^6,'03. Dulieutaichinhlamsach_RG'!K40)
A39: 2. Người mua trả tiền trước | B39: =IF(TRIM('03. Dulieutaichinhlamsach_RG'!$G$2)="VND",'03. Dulieutaichinhlamsach_RG'!D41/10^6,'03. Dulieutaichinhlamsach_RG'!D41) | C39: =IF(TRIM('03. Dulieutaichinhlamsach_RG'!$G$2)="VND",'03. Dulieutaichinhlamsach_RG'!E41/10^6,'03. Dulieutaichinhlamsach_RG'!E41) | D39: =IF(TRIM('03. Dulieutaichinhlamsach_RG'!$G$2)="VND",'03. Dulieutaichinhlamsach_RG'!F41/10^6,'03. Dulieutaichinhlamsach_RG'!F41) | E39: =IF($D$10<>0,D39/$D$10," ") | F39: =IF(C39<>0,(D39-C39)/C39,"") | G39: =IF(TRIM('03. Dulieutaichinhlamsach_RG'!$G$2)="VND",'03. Dulieutaichinhlamsach_RG'!I41/10^6,'03. Dulieutaichinhlamsach_RG'!I41) | H39: =IF($G$10<>0,G39/$G$10," ") | I39: =IF(TRIM('03. Dulieutaichinhlamsach_RG'!$G$2)="VND",'03. Dulieutaichinhlamsach_RG'!K41/10^6,'03. Dulieutaichinhlamsach_RG'!K41)
A40: 3. Thuế và các khoản phải nộp Nhà nước | B40: =IF(TRIM('03. Dulieutaichinhlamsach_RG'!$G$2)="VND",'03. Dulieutaichinhlamsach_RG'!D42/10^6,'03. Dulieutaichinhlamsach_RG'!D42) | C40: =IF(TRIM('03. Dulieutaichinhlamsach_RG'!$G$2)="VND",'03. Dulieutaichinhlamsach_RG'!E42/10^6,'03. Dulieutaichinhlamsach_RG'!E42) | D40: =IF(TRIM('03. Dulieutaichinhlamsach_RG'!$G$2)="VND",'03. Dulieutaichinhlamsach_RG'!F42/10^6,'03. Dulieutaichinhlamsach_RG'!F42) | E40: =IF($D$10<>0,D40/$D$10," ") | F40: =IF(C40<>0,(D40-C40)/C40,"") | G40: =IF(TRIM('03. Dulieutaichinhlamsach_RG'!$G$2)="VND",'03. Dulieutaichinhlamsach_RG'!I42/10^6,'03. Dulieutaichinhlamsach_RG'!I42) | H40: =IF($G$10<>0,G40/$G$10," ") | I40: =IF(TRIM('03. Dulieutaichinhlamsach_RG'!$G$2)="VND",'03. Dulieutaichinhlamsach_RG'!K42/10^6,'03. Dulieutaichinhlamsach_RG'!K42)
