Workbook

Sheet Chi tiết NVL
A1: CÔNG TY CỔ PHẦN KẾT CẤU THÉP STEELTECH
A2: MST: 0319777888
A4: NHẬP XUẤT TỒN
A5: Kỳ 01-12/2025
A7: Ngày chứng từ | B7: Số chứng từ nhập | C7: Ngày nhập hàng | D7: Số hóa đơn | E7: Ngày hóa đơn | F7: Số chứng từ xuất | G7: Ngày xuất hàng | H7: Nhà cung cấp | I7: Tên hàng | J7: ĐVT | K7: Đơn giá | L7: Tồn đầu kỳ | N7: Nhập trong kỳ | P7: Xuất trong kỳ | R7: Tồn cuối kỳ
L8: Số lượng | M8: Thành tiền | N8: Số lượng | O8: Thành tiền | P8: Số lượng | Q8: Thành tiền | R8: Số lượng | S8: Thành tiền
A9: 1 | B9: 2 | C9: 3 | D9: 4 | E9: 5 | F9: 6 | G9: 7 | H9: 8 | I9: 9 | J9: 10 | K9: 11 | L9: 12 | M9: 13 | N9: 14 | O9: 15 | P9: 16 | Q9: 17 | R9: 18 | S9: 19
A10: 45659 | B10: MH2501-01 | C10: 45659 | D10: 00000012 | E10: 45659 | F10: XK2501-01 | G10: 45659 | H10: CÔNG TY TNHH SƠN JOTUN VIỆT NAM | I10: SƠN JOTAMASTIC 70 GREY 18L | J10: Lít | K10: 90000 | N10: 1278 | O10: 115020000 | P10: 1278 | Q10: 115020000 | R10: =+L10+N10-P10 | S10: =+M10+O10-Q10
A11: 45659 | B11: MH2501-01 | C11: 45659 | D11: 00000012 | E11: 45659 | F11: XK2501-01 | G11: 45659 | H11: CÔNG TY TNHH SƠN JOTUN VIỆT NAM | I11: SƠN FUTURA CLASSIC RAL 9010 20L | J11: Lít | K11: 155000 | N11: 200 | O11: 31000000 | P11: 200 | Q11: 31000000 | R11: =+L11+N11-P11 | S11: =+M11+O11-Q11
A12: 45659 | B12: MH2501-01 | C12: 45659 | D12: 00000012 | E12: 45659 | F12: XK2501-01 | G12: 45659 | H12: CÔNG TY TNHH SƠN JOTUN VIỆT NAM | I12: SƠN FUTURA CLASSIC RAL9010 4.55L | J12: Lít | K12: 155000 | N12: 27.3 | O12: 4231500 | P12: 27.3 | Q12: 4231500 | R12: =+L12+N12-P12 | S12: =+M12+O12-Q12
A13: 45659 | B13: MH2501-01 | C13: 45659 | D13: 00000012 | E13: 45659 | F13: XK2501-01 | G13: 45659 | H13: CÔNG TY TNHH SƠN JOTUN VIỆT NAM | I13: DUNG MÔI JOTUN THINNER NO. 17 20L | J13: Lít | K13: 60000 | N13: 200 | O13: 12000000 | P13: 200 | Q13: 12000000 | R13: =+L13+N13-P13 | S13: =+M13+O13-Q13
A14: 45659 | B14: MH2501-01 | C14: 45659 | D14: 00000012 | E14: 45659 | F14: XK2501-01 | G14: 45659 | H14: CÔNG TY TNHH SƠN JOTUN VIỆT NAM | I14: DUNG MÔI JOTUN THINNER NO. 10 20L | J14: Lít | K14: 60000 | N14: 180 | O14: 10800000 | P14: 180 | Q14: 10800000 | R14: =+L14+N14-P14 | S14: =+M14+O14-Q14
A15: 45659 | B15: MH2501-01 | C15: 45659 | D15: 00000012 | E15: 45659 | F15: XK2501-01 | G15: 45659 | H15: CÔNG TY TNHH SƠN JOTUN VIỆT NAM | I15: SƠN FUTURA CLASSIC RAL9010 18.22L | J15: Lít | K15: 160000 | N15: 819.9 | O15: 131184000 | P15: 819.9 | Q15: 131184000 | R15: =+L15+N15-P15 | S15: =+M15+O15-Q15
A16: 45659 | B16: MH2501-02 | C16: 45659 | D16: 00000008 | E16: 45659 | F16: XK2501-02 | G16: 45659 | H16: CÔNG TY TNHH SƠN JOTUN VIỆT NAM | I16: SƠN JOTAMASTIC 70 GREY 18L | J16: Lít | K16: 90000 | N16: 396 | O16: 35640000 | P16: 396 | Q16: 35640000 | R16: =+L16+N16-P16 | S16: =+M16+O16-Q16
A17: 45659 | B17: MH2501-02 | C17: 45659 | D17: 00000008 | E17: 45659 | F17: XK2501-02 | G17: 45659 | H17: CÔNG TY TNHH SƠN JOTUN VIỆT NAM | I17: DUNG MÔI JOTUN THINNER NO. 17 20L | J17: Lít | K17: 60000 | N17: 60 | O17: 3600000 | P17: 60 | Q17: 3600000 | R17: =+L17+N17-P17 | S17: =+M17+O17-Q17
A18: 45659 | B18: MH2501-02 | C18: 45659 | D18: 00000008 | E18: 45659 | F18: XK2501-02 | G18: 45659 | H18: CÔNG TY TNHH SƠN JOTUN VIỆT NAM | I18: DUNG MÔI JOTUN THINNER NO. 10 20L | J18: Lít | K18: 60000 | N18: 40 | O18: 2400000 | P18: 40 | Q18: 2400000 | R18: =+L18+N18-P18 | S18: =+M18+O18-Q18
A19: 45659 | B19: MH2501-02 | C19: 45659 | D19: 00000008 | E19: 45659 | F19: XK2501-02 | G19: 45659 | H19: CÔNG TY TNHH SƠN JOTUN VIỆT NAM | I19: SƠN FUTURA CLASSIC RAL7037 19.03L | J19: Lít | K19: 155000 | N19: 228.36 | O19: 35395800 | P19: 228.36 | Q19: 35395800 | R19: =+L19+N19-P19 | S19: =+M19+O19-Q19
A20: 45659 | B20: MH2501-03 | C20: 45659 | D20: 00000001 | E20: 45659 | F20: XK2501-02 | G20: 45659 | H20: CÔNG TY TNHH XNK THÉP KIM NAM | I20: Thép tấm 6lyx1500x6000 | J20: kg | K20: 13981.82 | N20: 32216.4 | O20: 450443847 | P20: 32216.4 | Q20: 450443847 | R20: =+L20+N20-P20 | S20: =+M20+O20-Q20
A21: 45661 | B21: MH2501-06A | C21: 45661 | D21: 00000039 | E21: 45661 | F21: XK2501-04 | G21: 45661 | H21: CÔNG TY CỔ PHẦN CÔNG NGHIỆP VÀ THƯƠNG MẠI CƯỜNG THỊNH | I21: Vít B2 Dacromet 12-14x20 | J21: Cái | K21: 600 | N21: 1400 | O21: 840000 | P21: 1400 | Q21: 840000 | R21: =+L21+N21-P21 | S21: =+M21+O21-Q21
... A252: 45671 | B252: MH2501-33 | C252: 45671 | D252: 00000175 | E252: 45671 | F252: XK2501-20 | G252: 45671 | H252: CÔNG TY CỔ PHẦN CÔNG NGHIỆP VÀ THƯƠNG MẠI CƯỜNG THỊNH | I252: Long đền thường ZP M24B45D2 | J252: Cái | K252: 820 | N252: 227 | O252: 186140 | P252: 227 | Q252: 186140 | R252: =+L252+N252-P252 | S252: =+M252+O252-Q252
A253: 45671 | B253: MH2501-33 | C253: 45671 | D253: 00000176 | E253: 45671 | F253: XK2501-20 | G253: 45671 | H253: CÔNG TY CỔ PHẦN CÔNG NGHIỆP VÀ THƯƠNG MẠI CƯỜNG THỊNH | I253: Ty giằng 2 đầu ren 4.6 ZP M16 | K253: 48000 | N253: 86.46 | O253: 4150080 | P253: 86.46 | Q253: 4150080 | R253: =+L253+N253-P253 | S253: =+M253+O253-Q253
A254: 45671 | B254: MH2501-33 | C254: 45671 | D254: 00000176 | E254: 45671 | F254: XK2501-20 | G254: 45671 | H254: CÔNG TY CỔ PHẦN CÔNG NGHIỆP VÀ THƯƠNG MẠI CƯỜNG THỊNH | I254: Đai ốc Din 934 5 ZP M16 | J254: Cái | K254: 1110 | N254: 24 | O254: 26640 | P254: 24 | Q254: 26640 | R254: =+L254+N254-P254 | S254: =+M254+O254-Q254
A255: 45671 | B255: MH2501-33 | C255: 45671 | D255: 00000176 | E255: 45671 | F255: XK2501-20 | G255: 45671 | H255: CÔNG TY CỔ PHẦN CÔNG NGHIỆP VÀ THƯƠNG MẠI CƯỜNG THỊNH | I255: Long đền thường ZP M16B42D2 | J255: Cái | K255: 800 | N255: 24 | O255: 19200 | P255: 24 | Q255: 19200 | R255: =+L255+N255-P255 | S255: =+M255+O255-Q255
A256: 45671 | B256: MH2501-33 | C256: 45671 | D256: 00000176 | E256: 45671 | F256: XK2501-20 | G256: 45671 | H256: CÔNG TY CỔ PHẦN CÔNG NGHIỆP VÀ THƯƠNG MẠI CƯỜNG THỊNH | I256: Long đền móng ngựa ZP M16 | J256: Cái | K256: 15670 | N256: 24 | O256: 376080 | P256: 24 | Q256: 376080 | R256: =+L256+N256-P256 | S256: =+M256+O256-Q256
A257: 45671 | B257: MH2501-33 | C257: 45671 | D257: 00000176 | E257: 45671 | F257: XK2501-20 | G257: 45671 | H257: CÔNG TY CỔ PHẦN CÔNG NGHIỆP VÀ THƯƠNG MẠI CƯỜNG THỊNH | I257: Nối Ty ZP M16x100 (23mm) | J257: Cái | K257: 24160 | N257: 8 | O257: 193280 | P257: 8 | Q257: 193280 | R257: =+L257+N257-P257 | S257: =+M257+O257-Q257
A258: 45671 | B258: MH2501-33 | C258: 45671 | D258: 00000176 | E258: 45671 | F258: XK2501-20 | G258: 45671 | H258: CÔNG TY CỔ PHẦN CÔNG NGHIỆP VÀ THƯƠNG MẠI CƯỜNG THỊNH | I258: Ty giằng 2 đầu ren 4.6 Ф11.3-11.5mm ZP M12 | K258: 22500 | N258: 41.45 | O258: 932625 | P258: 41.45 | Q258: 932625 | R258: =+L258+N258-P258 | S258: =+M258+O258-Q258
A259: 45671 | B259: MH2501-33 | C259: 45671 | D259: 00000176 | E259: 45671 | F259: XK2501-20 | G259: 45671 | H259: CÔNG TY CỔ PHẦN CÔNG NGHIỆP VÀ THƯƠNG MẠI CƯỜNG THỊNH | I259: Ty giằng 2 đầu ren 4.6 Ф11.3-11.5mm ZP M12 | K259: 24500 | N259: 9.72 | O259: 238140 | P259: 9.72 | Q259: 238140 | R259: =+L259+N259-P259 | S259: =+M259+O259-Q259
A260: 45671 | B260: MH2501-33 | C260: 45671 | D260: 00000176 | E260: 45671 | F260: XK2501-20 | G260: 45671 | H260: CÔNG TY CỔ PHẦN CÔNG NGHIỆP VÀ THƯƠNG MẠI CƯỜNG THỊNH | I260: Đai ốc thường 4 ZP M12 (9mm) | J260: Cái | K260: 360 | N260: 152 | O260: 54720 | P260: 152 | Q260: 54720 | R260: =+L260+N260-P260 | S260: =+M260+O260-Q260
A261: 45671 | B261: MH2501-33 | C261: 45671 | D261: 00000176 | E261: 45671 | F261: XK2501-20 | G261: 45671 | H261: CÔNG TY CỔ PHẦN CÔNG NGHIỆP VÀ THƯƠNG MẠI CƯỜNG THỊNH | I261: Long đền thường ZP M12B26D1.5 | J261: Cái | K261: 190 | N261: 152 | O261: 28880 | P261: 152 | Q261: 28880 | R261: =+L261+N261-P261 | S261: =+M261+O261-Q261
A262: 45671 | B262: MH2501-34 | C262: 45671 | D262: 00000022 | E262: 45671 | F262: XK2501-21 | G262: 45671 | H262: CÔNG TY TNHH HILSET VIỆT NAM | I262: Hóa chất HIT-RE 500 V4 | J262: Gói | K262: 850340 | N262: 40 | O262: 34013600 | P262: 40 | Q262: 34013600 | R262: =+L262+N262-P262 | S262: =+M262+O262-Q262
A263: 45671 | B263: MH2501-35 | C263: 45671 | D263: 00000556 | E263: 45671 | F263: XK2501-22 | G263: 45671 | H263: CÔNG TY TNHH SƠN JOTUN VIỆT NAM | I263: SƠN FUTURA CLASSIC STD0139 18.81L | J263: Thùng | K263: 155000 | N263: 18.81 | O263: 2915550 | P263: 18.81 | Q263: 2915550 | R263: =+L263+N263-P263 | S263: =+M263+O263-Q263
A264: 45671 | B264: MH2501-36 | C264: 45671 | D264: 00000011 | E264: 45671 | F264: XK2501-23 | G264: 45671 | H264: CÔNG TY TNHH XNK THÉP KIM NAM | I264: Thép ống 26.65x2.0x6m - Đen | J264: kg | K264: 16168.67 | N264: 29.16 | O264: 471478 | P264: 29.16 | Q264: 471478 | R264: =+L264+N264-P264 | S264: =+M264+O264-Q264
A265: 45671 | B265: MH2501-36 | C265: 45671 | D265: 00000011 | E265: 45671 | F265: XK2501-23 | G265: 45671 | H265: CÔNG TY TNHH XNK THÉP KIM NAM | I265: Thép ống 42.2x3.0x6m - Đen | J265: kg | K265: 16168.67 | N265: 104.4 | O265: 1688009 | P265: 104.4 | Q265: 1688009 | R265: =+L265+N265-P265 | S265: =+M265+O265-Q265
A266: 45671 | B266: MH2501-36 | C266: 45671 | D266: 00000011 | E266: 45671 | F266: XK2501-23 | G266: 45671 | H266: CÔNG TY TNHH XNK THÉP KIM NAM | I266: Thép Hình I150x75x5x6m | J266: kg | K266: 16805.04 | N266: 84 | O266: 1411623 | P266: 84 | Q266: 1411623 | R266: =+L266+N266-P266 | S266: =+M266+O266-Q266
A267: 45671 | B267: MH2501-36 | C267: 45671 | D267: 00000011 | E267: 45671 | F267: XK2501-23 | G267: 45671 | H267: CÔNG TY TNHH XNK THÉP KIM NAM | I267: Thép hình V50x50x4x6m | J267: kg | K267: 15441.4 | N267: 18 | O267: 277945 | P267: 18 | Q267: 277945 | R267: =+L267+N267-P267 | S267: =+M267+O267-Q267
A268: 45671 | B268: MH2501-36 | C268: 45671 | D268: 00000011 | E268: 45671 | F268: XK2501-23 | G268: 45671 | H268: CÔNG TY TNHH XNK THÉP KIM NAM | I268: Thép hình V63x63x5x6m | J268: kg | K268: 15623.22 | N268: 112 | O268: 1749800 | P268: 112 | Q268: 1749800 | R268: =+L268+N268-P268 | S268: =+M268+O268-Q268
A269: 45671 | B269: MH2501-36 | C269: 45671 | D269: 00000011 | E269: 45671 | F269: XK2501-23 | G269: 45671 | H269: CÔNG TY TNHH XNK THÉP KIM NAM | I269: Hộp vuông 100x100x2.5x6m - Đen | J269: kg | K269: 16168.67 | N269: 593.97 | O269: 9603707 | P269: 593.97 | Q269: 9603707 | R269: =+L269+N269-P269 | S269: =+M269+O269-Q269
A270: 45671 | B270: MH2501-36 | C270: 45671 | D270: 00000011 | E270: 45671 | F270: XK2501-23 | G270: 45671 | H270: CÔNG TY TNHH XNK THÉP KIM NAM | I270: Thép hình U120x47x3.5x6m | J270: kg | K270: 15454.55 | N270: 42 | O270: 649091 | P270: 42 | Q270: 649091 | R270: =+L270+N270-P270 | S270: =+M270+O270-Q270
A271: 45671 | B271: MH2501-36 | C271: 45671 | D271: 00000011 | E271: 45671 | F271: XK2501-23 | G271: 45671 | H271: CÔNG TY TNHH XNK THÉP KIM NAM | I271: Thép hình U250x76x6x12m | J271: kg | K271: 14532.31 | N271: 547.2 | O271: 7952080 | P271: 547.2 | Q271: 7952080 | R271: =+L271+N271-P271 | S271: =+M271+O271-Q271
... A719: 45722 | B719: MH2503-09 | C719: 45722 | D719: 00000654 | E719: 45722 | F719: XK2503-09 | G719: 45722 | H719: CÔNG TY CỔ PHẦN CÔNG NGHIỆP VÀ THƯƠNG MẠI CƯỜNG THỊNH | I719: Ty giằng 2 đầu ren 4.6 ZP M16 | J719: Mét | K719: 48000 | N719: 25.55 | O719: 1226400 | P719: 25.55 | Q719: 1226400 | R719: =+L719+N719-P719 | S719: =+M719+O719-Q719
...

Sheet Tổng hợp 154
A1: CÔNG TY CỔ PHẦN KẾT CẤU THÉP STEELTECH
A2: MST: 0319777888
A4: BẢNG XUẤT NHẬP TỒN SẢN PHẨM DỞ DANG THEO TỪNG CÔNG TRÌNH
A5: Kỳ hoàn thuế 01/2025-12/2025
A8: Mã dự án | B8: Tên dự án | C8: Đầu kỳ | D8: Phát sinh nợ | E8: Phát sinh có | F8: Cuối kỳ
A9: 12-24 | B9: Scotland Cold Storage | C9: 577544137 | D9: 4536751540 | E9: 5114295677 | F9: =+C9+D9-E9
A10: 11-24 | B10: Polyland Distribution Center | C10: 29578184 | D10: 808295652 | E10: 837873836 | F10: =+C10+D10-E10
A11: 28-24 | B11: GARAGE IN INSULAR VILLAGE | C11: 94489529 | D11: 534653830 | E11: 629143359 | F11: =+C11+D11-E11
A12: 27-24 | B12: GLAN TRANSPORTATION TERMINAL | C12: 47244460 | D12: 656410416 | E12: 703654876 | F12: =+C12+D12-E12
A13: 04-25 | B13: WAREHOUSE 1500SQM | C13: 0 | D13: 1038023798 | E13: 1038023798 | F13: =+C13+D13-E13
A14: 05-24 | B14: 2 Unit Building Warehouse | C14: 2898268879 | D14: 8904594888 | E14: 11802863767 | F14: =+C14+D14-E14
A15: 02-24 | B15: Polylite Tanza Warehouse | C15: 5.4682849e+08 | D15: 2277724486 | E15: 2824552972 | F15: =+C15+D15-E15
A16: 06-25 | B16: STRUMMS RENOVATION | C16: 0 | D16: 673147381 | E16: 673147381 | F16: =+C16+D16-E16
A17: 05-25 | B17: ONE STOREY | C17: 0 | D17: 381716393 | E17: 381716393 | F17: =+C17+D17-E17
A18: 19-24 | B18: Medija Residence | C18: 57780000 | D18: 8830851900 | E18: 8888631900 | F18: =+C18+D18-E18
A19: 02-25 | B19: KALINISAN COMMERCIAL BUILDING | C19: 0 | D19: 1499225883 | E19: 1499225883 | F19: =+C19+D19-E19
A20: 32-24 | B20: RMM DRY WAREHOUSE | C20: 913784390 | D20: 413219770 | E20: 1327004160 | F20: =+C20+D20-E20
... A39: 15-25 | B39: Batangas City South Sports Development Center | C39: 0 | D39: 2079655375 | E39: 2079655375 | F39: =+C39+D39-E39
A40: 24-25 | B40: NISU | D40: 3129617086 | E40: 3129617086 | F40: =+C40+D40-E40
A41: 25-25 | B41: DIAMOND APARTMENT BUILDING | D41: 612649302 | E41: 612649302 | F41: =+C41+D41-E41
A42: 17-25 | B42: MATUTUM PINES MEDICAL CENTER | D42: 1534258493 | E42: 1534258493 | F42: =+C42+D42-E42
A43: 30-25 | B43: TOYOTA HANGAR | D43: 627529295 | E43: 627529295 | F43: =+C43+D43-E43
A44: 28-25 | B44: TOYOTA CPD EXPANSION | D44: 7170769548 | E44: 7170769548 | F44: =+C44+D44-E44
A45: 32-25 | B45: NIKE OUTLET IN SUBIC | D45: 5675112206 | E45: 5675112206 | F45: =+C45+D45-E45
A46: 31-25 | B46: PROPOSED THREE STOREY STEEL PARKING | D46: 1625192407 | E46: 1625192407 | F46: =+C46+D46-E46
A47: 29-25 | B47: CEBU DRY WAREHOUSE | D47: 2570437536 | E47: 2570437536 | F47: =+C47+D47-E47
A48: 37-25 | B48: Tacurong Bonifacio Pubic market | D48: 6577244477 | E48: 6577244477 | F48: =+C48+D48-E48
A49: 35-25 | B49: Kanthararak Project | D49: 771127264 | E49: 771127264 | F49: =+C49+D49-E49
A50: 34-25 | B50: SMX Extension | D50: 19719228234 | E50: 19719228234 | F50: =+C50+D50-E50
A51: 42-25 | B51: SUPPORT FRAME | D51: 287481338 | E51: 287481338 | F51: =+C51+D51-E51
A52: 39-25 | B52: SM City Sto. Tomas Expansion | D52: 1471492473 | E52: 0 | F52: =+C52+D52-E52
B53: Tổng | C53: =SUM(C9:C52) | D53: =SUM(D9:D52) | E53: =SUM(E9:E52) | F53: =SUM(F9:F52)
F56: Giám Đốc
F63: Nguyễn Văn Steeltech

Sheet Tổng hợp NVL
A1: CÔNG TY CỔ PHẦN KẾT CẤU THÉP STEELTECH
A2: MST: 0319777888
A4: BẢNG XUẤT NHẬP TỒN NGUYÊN VẬT LIỆU
A5: Kỳ hoàn thuế 01/2025-12/2025
A8: Tên hàng | B8: ĐVT | C8: Tồn đầu kỳ | E8: Nhập trong kỳ | G8: Xuất trong kỳ | I8: Tồn cuối kỳ
C9: Số lượng | D9: Thành tiền | E9: Số lượng | F9: Thành tiền | G9: Số lượng | H9: Thành tiền | I9: Số lượng | J9: Thành tiền
A10: 1 | B10: 2 | C10: 4 | D10: 5 | E10: 6 | F10: 7 | G10: 8 | H10: 9 | I10: 10 | J10: p
A11: {=+_xlfn.UNIQUE('Chi tiết NVL'!I10:I4158)} | B11: =+VLOOKUP(A11,'Chi tiết NVL'!$I$10:$J$4158,2,0) | C11: =+SUMIF('Chi tiết NVL'!$I:$I,$A11,'Chi tiết NVL'!L:L) | D11: =+SUMIF('Chi tiết NVL'!$I:$I,$A11,'Chi tiết NVL'!M:M) | E11: =+SUMIF('Chi tiết NVL'!$I:$I,$A11,'Chi tiết NVL'!N:N) | F11: =+SUMIF('Chi tiết NVL'!$I:$I,$A11,'Chi tiết NVL'!O:O) | G11: =+SUMIF('Chi tiết NVL'!$I:$I,$A11,'Chi tiết NVL'!P:P) | H11: =+SUMIF('Chi tiết NVL'!$I:$I,$A11,'Chi tiết NVL'!Q:Q) | I11: =+SUMIF('Chi tiết NVL'!$I:$I,$A11,'Chi tiết NVL'!R:R) | J11: =+SUMIF('Chi tiết NVL'!$I:$I,$A11,'Chi tiết NVL'!S:S)
A12: SƠN FUTURA CLASSIC RAL 9010 20L | B12: =+VLOOKUP(A12,'Chi tiết NVL'!$I$10:$J$4158,2,0) | C12: =+SUMIF('Chi tiết NVL'!$I:$I,$A12,'Chi tiết NVL'!L:L) | D12: =+SUMIF('Chi tiết NVL'!$I:$I,$A12,'Chi tiết NVL'!M:M) | E12: =+SUMIF('Chi tiết NVL'!$I:$I,$A12,'Chi tiết NVL'!N:N) | F12: =+SUMIF('Chi tiết NVL'!$I:$I,$A12,'Chi tiết NVL'!O:O) | G12: =+SUMIF('Chi tiết NVL'!$I:$I,$A12,'Chi tiết NVL'!P:P) | H12: =+SUMIF('Chi tiết NVL'!$I:$I,$A12,'Chi tiết NVL'!Q:Q) | I12: =+SUMIF('Chi tiết NVL'!$I:$I,$A12,'Chi tiết NVL'!R:R) | J12: =+SUMIF('Chi tiết NVL'!$I:$I,$A12,'Chi tiết NVL'!S:S)
A13: SƠN FUTURA CLASSIC RAL9010 4.55L | B13: =+VLOOKUP(A13,'Chi tiết NVL'!$I$10:$J$4158,2,0) | C13: =+SUMIF('Chi tiết NVL'!$I:$I,$A13,'Chi tiết NVL'!L:L) | D13: =+SUMIF('Chi tiết NVL'!$I:$I,$A13,'Chi tiết NVL'!M:M) | E13: =+SUMIF('Chi tiết NVL'!$I:$I,$A13,'Chi tiết NVL'!N:N) | F13: =+SUMIF('Chi tiết NVL'!$I:$I,$A13,'Chi tiết NVL'!O:O) | G13: =+SUMIF('Chi tiết NVL'!$I:$I,$A13,'Chi tiết NVL'!P:P) | H13: =+SUMIF('Chi tiết NVL'!$I:$I,$A13,'Chi tiết NVL'!Q:Q) | I13: =+SUMIF('Chi tiết NVL'!$I:$I,$A13,'Chi tiết NVL'!R:R) | J13: =+SUMIF('Chi tiết NVL'!$I:$I,$A13,'Chi tiết NVL'!S:S)
A14: DUNG MÔI JOTUN THINNER NO. 17 20L | B14: =+VLOOKUP(A14,'Chi tiết NVL'!$I$10:$J$4158,2,0) | C14: =+SUMIF('Chi tiết NVL'!$I:$I,$A14,'Chi tiết NVL'!L:L) | D14: =+SUMIF('Chi tiết NVL'!$I:$I,$A14,'Chi tiết NVL'!M:M) | E14: =+SUMIF('Chi tiết NVL'!$I:$I,$A14,'Chi tiết NVL'!N:N) | F14: =+SUMIF('Chi tiết NVL'!$I:$I,$A14,'Chi tiết NVL'!O:O) | G14: =+SUMIF('Chi tiết NVL'!$I:$I,$A14,'Chi tiết NVL'!P:P) | H14: =+SUMIF('Chi tiết NVL'!$I:$I,$A14,'Chi tiết NVL'!Q:Q) | I14: =+SUMIF('Chi tiết NVL'!$I:$I,$A14,'Chi tiết NVL'!R:R) | J14: =+SUMIF('Chi tiết NVL'!$I:$I,$A14,'Chi tiết NVL'!S:S)
A15: DUNG MÔI JOTUN THINNER NO. 10 20L | B15: =+VLOOKUP(A15,'Chi tiết NVL'!$I$10:$J$4158,2,0) | C15: =+SUMIF('Chi tiết NVL'!$I:$I,$A15,'Chi tiết NVL'!L:L) | D15: =+SUMIF('Chi tiết NVL'!$I:$I,$A15,'Chi tiết NVL'!M:M) | E15: =+SUMIF('Chi tiết NVL'!$I:$I,$A15,'Chi tiết NVL'!N:N) | F15: =+SUMIF('Chi tiết NVL'!$I:$I,$A15,'Chi tiết NVL'!O:O) | G15: =+SUMIF('Chi tiết NVL'!$I:$I,$A15,'Chi tiết NVL'!P:P) | H15: =+SUMIF('Chi tiết NVL'!$I:$I,$A15,'Chi tiết NVL'!Q:Q) | I15: =+SUMIF('Chi tiết NVL'!$I:$I,$A15,'Chi tiết NVL'!R:R) | J15: =+SUMIF('Chi tiết NVL'!$I:$I,$A15,'Chi tiết NVL'!S:S)
A16: SƠN FUTURA CLASSIC RAL9010 18.22L | B16: =+VLOOKUP(A16,'Chi tiết NVL'!$I$10:$J$4158,2,0) | C16: =+SUMIF('Chi tiết NVL'!$I:$I,$A16,'Chi tiết NVL'!L:L) | D16: =+SUMIF('Chi tiết NVL'!$I:$I,$A16,'Chi tiết NVL'!M:M) | E16: =+SUMIF('Chi tiết NVL'!$I:$I,$A16,'Chi tiết NVL'!N:N) | F16: =+SUMIF('Chi tiết NVL'!$I:$I,$A16,'Chi tiết NVL'!O:O) | G16: =+SUMIF('Chi tiết NVL'!$I:$I,$A16,'Chi tiết NVL'!P:P) | H16: =+SUMIF('Chi tiết NVL'!$I:$I,$A16,'Chi tiết NVL'!Q:Q) | I16: =+SUMIF('Chi tiết NVL'!$I:$I,$A16,'Chi tiết NVL'!R:R) | J16: =+SUMIF('Chi tiết NVL'!$I:$I,$A16,'Chi tiết NVL'!S:S)
A17: SƠN FUTURA CLASSIC RAL7037 19.03L | B17: =+VLOOKUP(A17,'Chi tiết NVL'!$I$10:$J$4158,2,0) | C17: =+SUMIF('Chi tiết NVL'!$I:$I,$A17,'Chi tiết NVL'!L:L) | D17: =+SUMIF('Chi tiết NVL'!$I:$I,$A17,'Chi tiết NVL'!M:M) | E17: =+SUMIF('Chi tiết NVL'!$I:$I,$A17,'Chi tiết NVL'!N:N) | F17: =+SUMIF('Chi tiết NVL'!$I:$I,$A17,'Chi tiết NVL'!O:O) | G17: =+SUMIF('Chi tiết NVL'!$I:$I,$A17,'Chi tiết NVL'!P:P) | H17: =+SUMIF('Chi tiết NVL'!$I:$I,$A17,'Chi tiết NVL'!Q:Q) | I17: =+SUMIF('Chi tiết NVL'!$I:$I,$A17,'Chi tiết NVL'!R:R) | J17: =+SUMIF('Chi tiết NVL'!$I:$I,$A17,'Chi tiết NVL'!S:S)
A18: Thép tấm 6lyx1500x6000 | B18: =+VLOOKUP(A18,'Chi tiết NVL'!$I$10:$J$4158,2,0) | C18: =+SUMIF('Chi tiết NVL'!$I:$I,$A18,'Chi tiết NVL'!L:L) | D18: =+SUMIF('Chi tiết NVL'!$I:$I,$A18,'Chi tiết NVL'!M:M) | E18: =+SUMIF('Chi tiết NVL'!$I:$I,$A18,'Chi tiết NVL'!N:N) | F18: =+SUMIF('Chi tiết NVL'!$I:$I,$A18,'Chi tiết NVL'!O:O) | G18: =+SUMIF('Chi tiết NVL'!$I:$I,$A18,'Chi tiết NVL'!P:P) | H18: =+SUMIF('Chi tiết NVL'!$I:$I,$A18,'Chi tiết NVL'!Q:Q) | I18: =+SUMIF('Chi tiết NVL'!$I:$I,$A18,'Chi tiết NVL'!R:R) | J18: =+SUMIF('Chi tiết NVL'!$I:$I,$A18,'Chi tiết NVL'!S:S)
A19: Vít B2 Dacromet 12-14x20 | B19: =+VLOOKUP(A19,'Chi tiết NVL'!$I$10:$J$4158,2,0) | C19: =+SUMIF('Chi tiết NVL'!$I:$I,$A19,'Chi tiết NVL'!L:L) | D19: =+SUMIF('Chi tiết NVL'!$I:$I,$A19,'Chi tiết NVL'!M:M) | E19: =+SUMIF('Chi tiết NVL'!$I:$I,$A19,'Chi tiết NVL'!N:N) | F19: =+SUMIF('Chi tiết NVL'!$I:$I,$A19,'Chi tiết NVL'!O:O) | G19: =+SUMIF('Chi tiết NVL'!$I:$I,$A19,'Chi tiết NVL'!P:P) | H19: =+SUMIF('Chi tiết NVL'!$I:$I,$A19,'Chi tiết NVL'!Q:Q) | I19: =+SUMIF('Chi tiết NVL'!$I:$I,$A19,'Chi tiết NVL'!R:R) | J19: =+SUMIF('Chi tiết NVL'!$I:$I,$A19,'Chi tiết NVL'!S:S)
A20: Đinh hàn 4.8 M19x100 | B20: =+VLOOKUP(A20,'Chi tiết NVL'!$I$10:$J$4158,2,0) | C20: =+SUMIF('Chi tiết NVL'!$I:$I,$A20,'Chi tiết NVL'!L:L) | D20: =+SUMIF('Chi tiết NVL'!$I:$I,$A20,'Chi tiết NVL'!M:M) | E20: =+SUMIF('Chi tiết NVL'!$I:$I,$A20,'Chi tiết NVL'!N:N) | F20: =+SUMIF('Chi tiết NVL'!$I:$I,$A20,'Chi tiết NVL'!O:O) | G20: =+SUMIF('Chi tiết NVL'!$I:$I,$A20,'Chi tiết NVL'!P:P) | H20: =+SUMIF('Chi tiết NVL'!$I:$I,$A20,'Chi tiết NVL'!Q:Q) | I20: =+SUMIF('Chi tiết NVL'!$I:$I,$A20,'Chi tiết NVL'!R:R) | J20: =+SUMIF('Chi tiết NVL'!$I:$I,$A20,'Chi tiết NVL'!S:S)
A21: Vít B2 Dacromet 12-24x38 HWFS (lục giác) | B21: =+VLOOKUP(A21,'Chi tiết NVL'!$I$10:$J$4158,2,0) | C21: =+SUMIF('Chi tiết NVL'!$I:$I,$A21,'Chi tiết NVL'!L:L) | D21: =+SUMIF('Chi tiết NVL'!$I:$I,$A21,'Chi tiết NVL'!M:M) | E21: =+SUMIF('Chi tiết NVL'!$I:$I,$A21,'Chi tiết NVL'!N:N) | F21: =+SUMIF('Chi tiết NVL'!$I:$I,$A21,'Chi tiết NVL'!O:O) | G21: =+SUMIF('Chi tiết NVL'!$I:$I,$A21,'Chi tiết NVL'!P:P) | H21: =+SUMIF('Chi tiết NVL'!$I:$I,$A21,'Chi tiết NVL'!Q:Q) | I21: =+SUMIF('Chi tiết NVL'!$I:$I,$A21,'Chi tiết NVL'!R:R) | J21: =+SUMIF('Chi tiết NVL'!$I:$I,$A21,'Chi tiết NVL'!S:S)
A22: Bulong Din 933 8.8 ZP M20x60 | B22: =+VLOOKUP(A22,'Chi tiết NVL'!$I$10:$J$4158,2,0) | C22: =+SUMIF('Chi tiết NVL'!$I:$I,$A22,'Chi tiết NVL'!L:L) | D22: =+SUMIF('Chi tiết NVL'!$I:$I,$A22,'Chi tiết NVL'!M:M) | E22: =+SUMIF('Chi tiết NVL'!$I:$I,$A22,'Chi tiết NVL'!N:N) | F22: =+SUMIF('Chi tiết NVL'!$I:$I,$A22,'Chi tiết NVL'!O:O) | G22: =+SUMIF('Chi tiết NVL'!$I:$I,$A22,'Chi tiết NVL'!P:P) | H22: =+SUMIF('Chi tiết NVL'!$I:$I,$A22,'Chi tiết NVL'!Q:Q) | I22: =+SUMIF('Chi tiết NVL'!$I:$I,$A22,'Chi tiết NVL'!R:R) | J22: =+SUMIF('Chi tiết NVL'!$I:$I,$A22,'Chi tiết NVL'!S:S)
A23: Đai ốc Din 934 8 ZP M20 | B23: =+VLOOKUP(A23,'Chi tiết NVL'!$I$10:$J$4158,2,0) | C23: =+SUMIF('Chi tiết NVL'!$I:$I,$A23,'Chi tiết NVL'!L:L) | D23: =+SUMIF('Chi tiết NVL'!$I:$I,$A23,'Chi tiết NVL'!M:M) | E23: =+SUMIF('Chi tiết NVL'!$I:$I,$A23,'Chi tiết NVL'!N:N) | F23: =+SUMIF('Chi tiết NVL'!$I:$I,$A23,'Chi tiết NVL'!O:O) | G23: =+SUMIF('Chi tiết NVL'!$I:$I,$A23,'Chi tiết NVL'!P:P) | H23: =+SUMIF('Chi tiết NVL'!$I:$I,$A23,'Chi tiết NVL'!Q:Q) | I23: =+SUMIF('Chi tiết NVL'!$I:$I,$A23,'Chi tiết NVL'!R:R) | J23: =+SUMIF('Chi tiết NVL'!$I:$I,$A23,'Chi tiết NVL'!S:S)
... A872: Cung cấp cửa chớp thép theo báo giá số: 014425/BGXK/LTL-RM ký ngày 03/12/2025 | B872: =+VLOOKUP(A872,'Chi tiết NVL'!$I$10:$J$4158,2,0) | C872: =+SUMIF('Chi tiết NVL'!$I:$I,$A872,'Chi tiết NVL'!L:L) | D872: =+SUMIF('Chi tiết NVL'!$I:$I,$A872,'Chi tiết NVL'!M:M) | E872: =+SUMIF('Chi tiết NVL'!$I:$I,$A872,'Chi tiết NVL'!N:N) | F872: =+SUMIF('Chi tiết NVL'!$I:$I,$A872,'Chi tiết NVL'!O:O) | G872: =+SUMIF('Chi tiết NVL'!$I:$I,$A872,'Chi tiết NVL'!P:P) | H872: =+SUMIF('Chi tiết NVL'!$I:$I,$A872,'Chi tiết NVL'!Q:Q) | I872: =+SUMIF('Chi tiết NVL'!$I:$I,$A872,'Chi tiết NVL'!R:R) | J872: =+SUMIF('Chi tiết NVL'!$I:$I,$A872,'Chi tiết NVL'!S:S)
A873: Tổng cộng | C873: =SUM(C11:C872) | D873: =SUM(D11:D872) | E873: =SUM(E11:E872) | F873: =SUM(F11:F872) | G873: =SUM(G11:G872) | H873: =SUM(H11:H872) | I873: =SUM(I11:I872) | J873: =SUM(J11:J872)
H876: Giám Đốc
E878: ĐK | F878: CK
D879: XNT | E879: 0 | F879: 0
D880: TK 154 | E880: 6.071337e+09 | F880: 1.4714925e+09
D881: Tổng cộng | E881: =+E879+E880 | F881: =+F879+F880
H883: Nguyễn Văn Steeltech
